Workbook

Sheet 1.NPS대시보드
B2: | NPS(Net Promoter Score) 대시보드 | BD2: {{cm_yyyymmdd}}
B4: ■ Bottom-up NPS
B6: - 금융업계의 평균적인 NPS 수준은 10 ~ 40점으로, 50점 이상이면 높은 고객 충성도를 유지∙기대, 0점 이하면 서비스 개선이 필요한 상황
B7: - {{S1_script1}}
C10: 종합 NPS | N10: 스타뱅킹 NPS | Y10: 영업점 NPS | AJ10: 고객센터NPS | AU10: 상품 NPS
D12: =IFERROR(VALUE(VLOOKUP("종합", BU_NPS_RAW!$A:$B, 2, FALSE)),0) -> 0 | O12: =IFERROR(VALUE(VLOOKUP("KB 스타뱅킹", BU_NPS_RAW!$A:$B, 2, FALSE)),0) -> 0 | W12: 56.6 | Z12: =IFERROR(VALUE(VLOOKUP("영업점", BU_NPS_RAW!$A:$B, 2, FALSE)),0) -> 0 | AH12: 57.16 | AK12: =IFERROR(VALUE(VLOOKUP("고객센터", BU_NPS_RAW!$A:$B, 2, FALSE)),0) -> 0 | AS12: 63.05 | AV12: =IFERROR(VALUE(VLOOKUP(B42, BU_NPS_RAW!$A:$B, 2, FALSE)),0) -> 0 | BD12: 22.44
C14: 전주 대비 | I14: =IFERROR(VALUE(VLOOKUP("종합", BU_NPS_RAW!$A:$C, 3, FALSE)),0) -> 0 | N14: 전주 대비 | T14: =IFERROR(VALUE(VLOOKUP("KB 스타뱅킹", BU_NPS_RAW!$A:$C, 3, FALSE)),0) -> 0 | Y14: 전주 대비 | AE14: =IFERROR(VALUE(VLOOKUP("영업점", BU_NPS_RAW!$A:$C, 3, FALSE)),0) -> 0 | AJ14: 전주 대비 | AP14: =IFERROR(VALUE(VLOOKUP("고객센터", BU_NPS_RAW!$A:$C, 3, FALSE)),0) -> 0 | AU14: 전주 대비 | BA14: =IFERROR(VALUE(VLOOKUP(B42, BU_NPS_RAW!$A:$C, 3, FALSE)),0) -> 0
C15: 전월 대비 | I15: =IFERROR(VALUE(VLOOKUP("종합", BU_NPS_RAW!$A:$D, 4, FALSE)),0) -> 0 | N15: 전월 대비 | T15: =IFERROR(VALUE(VLOOKUP("KB 스타뱅킹", BU_NPS_RAW!$A:$D, 4, FALSE)),0) -> 0 | Y15: 전월 대비 | AE15: =IFERROR(VALUE(VLOOKUP("영업점", BU_NPS_RAW!$A:$D, 4, FALSE)),0) -> 0 | AJ15: 전월 대비 | AP15: =IFERROR(VALUE(VLOOKUP("고객센터", BU_NPS_RAW!$A:$D, 4, FALSE)),0) -> 0 | AU15: 전월 대비 | BA15: =IFERROR(VALUE(VLOOKUP(B42, BU_NPS_RAW!$A:$D, 4, FALSE)),0) -> 0
B18: ■ 설문진행 현황
C21: 총 발송건수 | Q21: 총 응답접속수 | AE21: 총 응답완료수 | AS21: 응답률
D23: {{S1_총발송건수_1}} | R23: {{S1_총응답접속수_1}} | AB23: {{S1_총응답접속수_1}} | AF23: {{S1_총응답완료수_1}} | AP23: {{S1_총응답완료수_1}} | AT23: {{S1_응답률_1}} | BD23: {{S1_응답률_1}}
B26: ■ NPS 관리활동
C28: 구분 | M28: 인입건수 | AC28: 배분건수 | AG28: 검토건수 | AW28: 검토율
F29: 사업그룹 | M29: (단위 : 건) | Q29: 긍정 | U29: 부정 | Y29: 중립 | AC29: (단위 : 건) | AG29: (단위 : 건) | AK29: 현행유지 | AO29: 개선불가 | AS29: 개선예정 | AW29: (단위 : %, %p)
B30: 스타뱅킹 | F30: 디지털영업그룹 | M30: =SUM(Q30:AB30) -> 0 | Q30: =COUNTIFS(NPS관리활동_RAW!$D:$D, "KB 스타뱅킹", NPS관리활동_RAW!$I:$I, $F30, NPS관리활동_RAW!$G:$G, "긍정") -> 0 | U30: =COUNTIFS(NPS관리활동_RAW!$D:$D, "KB 스타뱅킹", NPS관리활동_RAW!$I:$I, $F30, NPS관리활동_RAW!$G:$G, "부정") -> 0 | Y30: =COUNTIFS(NPS관리활동_RAW!$D:$D, "KB 스타뱅킹", NPS관리활동_RAW!$I:$I, $F30, NPS관리활동_RAW!$G:$G, "중립") -> 0 | AC30: =COUNTIFS(NPS관리활동_RAW!$D:$D, "KB 스타뱅킹", NPS관리활동_RAW!$I:$I, "디지털영업그룹", NPS관리활동_RAW!$K:$K, "배분") -> 0 | AG30: =SUM(AK30:AV30) -> 0 | AK30: =COUNTIFS(NPS관리활동_RAW!$D:$D, "KB 스타뱅킹", NPS관리활동_RAW!$I:$I, F30, NPS관리활동_RAW!$L:$L, "현행유지") -> 0 | AO30: =COUNTIFS(NPS관리활동_RAW!$D:$D, "KB 스타뱅킹", NPS관리활동_RAW!$I:$I, F30, NPS관리활동_RAW!$L:$L, "개선불가") -> 0 | AS30: =COUNTIFS(NPS관리활동_RAW!$D:$D, "KB 스타뱅킹", NPS관리활동_RAW!$I:$I, F30, NPS관리활동_RAW!$L:$L, "개선예정") -> 0 | AW30: =IFERROR(AG30/AC30,0) -> 0
F31: 개인고객그룹 | M31: =SUM(Q31:AB31) -> 0 | Q31: =COUNTIFS(NPS관리활동_RAW!$D:$D, "KB 스타뱅킹", NPS관리활동_RAW!$I:$I, $F31, NPS관리활동_RAW!$G:$G, "긍정") -> 0 | U31: =COUNTIFS(NPS관리활동_RAW!$D:$D, "KB 스타뱅킹", NPS관리활동_RAW!$I:$I, $F31, NPS관리활동_RAW!$G:$G, "부정") -> 0 | Y31: =COUNTIFS(NPS관리활동_RAW!$D:$D, "KB 스타뱅킹", NPS관리활동_RAW!$I:$I, $F31, NPS관리활동_RAW!$G:$G, "중립") -> 0 | AC31: =COUNTIFS(NPS관리활동_RAW!$D:$D, "KB 스타뱅킹", NPS관리활동_RAW!$I:$I, F42, NPS관리활동_RAW!$K:$K, "배분") -> 0 | AG31: =SUM(AK31:AV31) -> 0 | AK31: =COUNTIFS(NPS관리활동_RAW!$D:$D, "KB 스타뱅킹", NPS관리활동_RAW!$I:$I, F31, NPS관리활동_RAW!$L:$L, "현행유지") -> 0 | AO31: =COUNTIFS(NPS관리활동_RAW!$D:$D, "KB 스타뱅킹", NPS관리활동_RAW!$I:$I, F31, NPS관리활동_RAW!$L:$L, "개선불가") -> 0 | AS31: =COUNTIFS(NPS관리활동_RAW!$D:$D, "KB 스타뱅킹", NPS관리활동_RAW!$I:$I, F31, NPS관리활동_RAW!$L:$L, "개선예정") -> 0 | AW31: =IFERROR(AG31/AC31,0) -> 0
F32: WM고객그룹 | M32: =SUM(Q32:AB32) -> 0 | Q32: =COUNTIFS(NPS관리활동_RAW!$D:$D, "KB 스타뱅킹", NPS관리활동_RAW!$I:$I, $F32, NPS관리활동_RAW!$G:$G, "긍정") -> 0 | U32: =COUNTIFS(NPS관리활동_RAW!$D:$D, "KB 스타뱅킹", NPS관리활동_RAW!$I:$I, $F32, NPS관리활동_RAW!$G:$G, "부정") -> 0 | Y32: =COUNTIFS(NPS관리활동_RAW!$D:$D, "KB 스타뱅킹", NPS관리활동_RAW!$I:$I, $F32, NPS관리활동_RAW!$G:$G, "중립") -> 0 | AC32: =COUNTIFS(NPS관리활동_RAW!$D:$D, "KB 스타뱅킹", NPS관리활동_RAW!$I:$I, F43, NPS관리활동_RAW!$K:$K, "배분") -> 0 | AG32: =SUM(AK32:AV32) -> 0 | AK32: =COUNTIFS(NPS관리활동_RAW!$D:$D, "KB 스타뱅킹", NPS관리활동_RAW!$I:$I, F32, NPS관리활동_RAW!$L:$L, "현행유지") -> 0 | AO32: =COUNTIFS(NPS관리활동_RAW!$D:$D, "KB 스타뱅킹", NPS관리활동_RAW!$I:$I, F32, NPS관리활동_RAW!$L:$L, "개선불가") -> 0 | AS32: =COUNTIFS(NPS관리활동_RAW!$D:$D, "KB 스타뱅킹", NPS관리활동_RAW!$I:$I, F32, NPS관리활동_RAW!$L:$L, "개선예정") -> 0 | AW32: =IFERROR(AG32/AC32,0) -> 0
F33: 기업고객그룹 | M33: =SUM(Q33:AB33) -> 0 | Q33: =COUNTIFS(NPS관리활동_RAW!$D:$D, "KB 스타뱅킹", NPS관리활동_RAW!$I:$I, $F33, NPS관리활동_RAW!$G:$G, "긍정") -> 0 | U33: =COUNTIFS(NPS관리활동_RAW!$D:$D, "KB 스타뱅킹", NPS관리활동_RAW!$I:$I, $F33, NPS관리활동_RAW!$G:$G, "부정") -> 0 | Y33: =COUNTIFS(NPS관리활동_RAW!$D:$D, "KB 스타뱅킹", NPS관리활동_RAW!$I:$I, $F33, NPS관리활동_RAW!$G:$G, "중립") -> 0 | AC33: =COUNTIFS(NPS관리활동_RAW!$D:$D, "KB 스타뱅킹", NPS관리활동_RAW!$I:$I, F44, NPS관리활동_RAW!$K:$K, "배분") -> 0 | AG33: =SUM(AK33:AV33) -> 0 | AK33: =COUNTIFS(NPS관리활동_RAW!$D:$D, "KB 스타뱅킹", NPS관리활동_RAW!$I:$I, F33, NPS관리활동_RAW!$L:$L, "현행유지") -> 0 | AO33: =COUNTIFS(NPS관리활동_RAW!$D:$D, "KB 스타뱅킹", NPS관리활동_RAW!$I:$I, F33, NPS관리활동_RAW!$L:$L, "개선불가") -> 0 | AS33: =COUNTIFS(NPS관리활동_RAW!$D:$D, "KB 스타뱅킹", NPS관리활동_RAW!$I:$I, F33, NPS관리활동_RAW!$L:$L, "개선예정") -> 0 | AW33: =IFERROR(AG33/AC33,0) -> 0
F34: 기타 | M34: =SUM(Q34:AB34) -> 0 | Q34: {=SUM(COUNTIFS(NPS관리활동_RAW!$D:$D, "KB 스타뱅킹", NPS관리활동_RAW!$G:$G, "긍정")) - SUM(COUNTIFS(NPS관리활동_RAW!$D:$D, "KB 스타뱅킹", NPS관리활동_RAW!$I:$I, F30:F33, NPS관리활동_RAW!$G:$G, "긍정"))} -> 0 | U34: {=SUM(COUNTIFS(NPS관리활동_RAW!$D:$D, "KB 스타뱅킹", NPS관리활동_RAW!$G:$G, "부정")) - SUM(COUNTIFS(NPS관리활동_RAW!$D:$D, "KB 스타뱅킹", NPS관리활동_RAW!$I:$I, F30:F33, NPS관리활동_RAW!$G:$G, "부정"))} -> 0 | Y34: {=SUM(COUNTIFS(NPS관리활동_RAW!$D:$D, "KB 스타뱅킹", NPS관리활동_RAW!$G:$G, "중립")) - SUM(COUNTIFS(NPS관리활동_RAW!$D:$D, "KB 스타뱅킹", NPS관리활동_RAW!$I:$I, F30:F33, NPS관리활동_RAW!$G:$G, "중립"))} -> 0 | AC34: =COUNTIFS(NPS관리활동_RAW!$D:$D, "KB 스타뱅킹", NPS관리활동_RAW!$I:$I, "<>디지털영업그룹", NPS관리활동_RAW!$I:$I, "<>개인고객그룹", NPS관리활동_RAW!$I:$I, "<>WM고객그룹", NPS관리활동_RAW!$I:$I, "<>기업고객그룹", NPS관리활동_RAW!$K:$K, "배분") -> 0 | AG34: =SUM(AK34:AV34) -> 0 | AK34: {=SUM(COUNTIFS(NPS관리활동_RAW!$D:$D, "KB 스타뱅킹", NPS관리활동_RAW!$L:$L, "현행유지")) - SUM(COUNTIFS(NPS관리활동_RAW!$D:$D, "KB 스타뱅킹", NPS관리활동_RAW!$I:$I, F30:F33, NPS관리활동_RAW!$L:$L, "현행유지"))} -> 0 | AO34: {=SUM(COUNTIFS(NPS관리활동_RAW!$D:$D, "KB 스타뱅킹", NPS관리활동_RAW!$L:$L, "개선불가")) - SUM(COUNTIFS(NPS관리활동_RAW!$D:$D, "KB 스타뱅킹", NPS관리활동_RAW!$I:$I, F30:F33, NPS관리활동_RAW!$L:$L, "개선불가"))} -> 0 | AS34: {=SUM(COUNTIFS(NPS관리활동_RAW!$D:$D, "KB 스타뱅킹", NPS관리활동_RAW!$L:$L, "개선예정")) - SUM(COUNTIFS(NPS관리활동_RAW!$D:$D, "KB 스타뱅킹", NPS관리활동_RAW!$I:$I, F30:F33, NPS관리활동_RAW!$L:$L, "개선예정"))} -> 0 | AW34: =IFERROR(AG34/AC34,0) -> 0
F35: 소계 | M35: =SUM(M30:P34) -> 0 | Q35: =SUM(Q30:T34) -> 0 | U35: =SUM(U30:X34) -> 0 | Y35: =SUM(Y30:AB34) -> 0 | AC35: =SUM(AC30:AF34) -> 0 | AG35: =SUM(AG30:AJ34) -> 0 | AK35: =SUM(AK30:AN34) -> 0 | AO35: =SUM(AO30:AR34) -> 0 | AS35: =SUM(AS30:AV34) -> 0 | AW35: =IFERROR(AG35/AC35,0) -> 0
B36: 영업점 | F36: 영업기획그룹 | M36: =SUM(Q36:AB36) -> 0 | Q36: =COUNTIFS(NPS관리활동_RAW!$D:$D, $B$36, NPS관리활동_RAW!$I:$I, $F36, NPS관리활동_RAW!$G:$G, "긍정") -> 0 | U36: =COUNTIFS(NPS관리활동_RAW!$D:$D, $B$36, NPS관리활동_RAW!$I:$I, $F36, NPS관리활동_RAW!$G:$G, "부정") -> 0 | Y36: =COUNTIFS(NPS관리활동_RAW!$D:$D, $B$36, NPS관리활동_RAW!$I:$I, $F36, NPS관리활동_RAW!$G:$G, "중립") -> 0 | AC36: =COUNTIFS(NPS관리활동_RAW!$D:$D, "영업점", NPS관리활동_RAW!$I:$I, "영업기획그룹", NPS관리활동_RAW!$K:$K, "배분") -> 0 | AG36: =SUM(AK36:AV36) -> 0 | AK36: =COUNTIFS(NPS관리활동_RAW!$D:$D, B36, NPS관리활동_RAW!$I:$I, F36, NPS관리활동_RAW!$L:$L, "현행유지") -> 0 | AO36: =COUNTIFS(NPS관리활동_RAW!$D:$D, B36, NPS관리활동_RAW!$I:$I, F36, NPS관리활동_RAW!$L:$L, "개선불가") -> 0 | AS36: =COUNTIFS(NPS관리활동_RAW!$D:$D, B36, NPS관리활동_RAW!$I:$I, F36, NPS관리활동_RAW!$L:$L, "개선예정") -> 0 | AW36: =IFERROR(AG36/AC36,0) -> 0
F37: 기타 | M37: =SUM(Q37:AB37) -> 0 | Q37: =SUM(COUNTIFS(NPS관리활동_RAW!$D:$D, $B$36, NPS관리활동_RAW!$G:$G, "긍정")) - SUM(COUNTIFS(NPS관리활동_RAW!$D:$D, $B$36, NPS관리활동_RAW!$I:$I, F36, NPS관리활동_RAW!$G:$G, "긍정")) -> 0 | U37: =SUM(COUNTIFS(NPS관리활동_RAW!$D:$D, $B$36, NPS관리활동_RAW!$G:$G, "부정")) - SUM(COUNTIFS(NPS관리활동_RAW!$D:$D, $B$36, NPS관리활동_RAW!$I:$I, F36, NPS관리활동_RAW!$G:$G, "부정")) -> 0 | Y37: =SUM(COUNTIFS(NPS관리활동_RAW!$D:$D, $B$36, NPS관리활동_RAW!$G:$G, "중립")) - SUM(COUNTIFS(NPS관리활동_RAW!$D:$D, $B$36, NPS관리활동_RAW!$I:$I, F36, NPS관리활동_RAW!$G:$G, "중립")) -> 0 | AC37: =COUNTIFS(NPS관리활동_RAW!$D:$D, "영업점", NPS관리활동_RAW!$I:$I, "<>영업기획그룹", NPS관리활동_RAW!$K:$K, "배분") -> 0 | AG37: =SUM(AK37:AV37) -> 0 | AK37: =SUM(COUNTIFS(NPS관리활동_RAW!$D:$D, B36, NPS관리활동_RAW!$L:$L, "현행유지")) - SUM(COUNTIFS(NPS관리활동_RAW!$D:$D, B36, NPS관리활동_RAW!$I:$I, F36, NPS관리활동_RAW!$L:$L, "현행유지")) -> 0 | AO37: =SUM(COUNTIFS(NPS관리활동_RAW!$D:$D, B36, NPS관리활동_RAW!$L:$L, "개선불가")) - SUM(COUNTIFS(NPS관리활동_RAW!$D:$D, B36, NPS관리활동_RAW!$I:$I, F36, NPS관리활동_RAW!$L:$L, "개선불가")) -> 0 | AS37: =SUM(COUNTIFS(NPS관리활동_RAW!$D:$D, B36, NPS관리활동_RAW!$L:$L, "개선예정")) - SUM(COUNTIFS(NPS관리활동_RAW!$D:$D, B36, NPS관리활동_RAW!$I:$I, F36, NPS관리활동_RAW!$L:$L, "개선예정")) -> 0 | AW37: =IFERROR(AG37/AC37,0) -> 0
F38: 소계 | M38: =SUM(M36:P37) -> 0 | Q38: =SUM(Q36:T37) -> 0 | U38: =SUM(U36:X37) -> 0 | Y38: =SUM(Y36:AB37) -> 0 | AC38: =SUM(AC36,AC37) -> 0 | AG38: =SUM(AG36,AG37) -> 0 | AK38: =SUM(AK36,AK37) -> 0 | AO38: =SUM(AO36,AO37) -> 0 | AS38: =SUM(AS36,AS37) -> 0 | AW38: =IFERROR(AG38/AC38,0) -> 0
B39: 고객센터 | F39: 고객컨택영업그룹 | M39: =SUM(Q39:AB39) -> 0 | Q39: =COUNTIFS(NPS관리활동_RAW!$D:$D, $B$39, NPS관리활동_RAW!$I:$I, $F39, NPS관리활동_RAW!$G:$G, "긍정") -> 0 | U39: =COUNTIFS(NPS관리활동_RAW!$D:$D, $B$39, NPS관리활동_RAW!$I:$I, $F39, NPS관리활동_RAW!$G:$G, "부정") -> 0 | Y39: =COUNTIFS(NPS관리활동_RAW!$D:$D, $B$39, NPS관리활동_RAW!$I:$I, $F39, NPS관리활동_RAW!$G:$G, "중립") -> 0 | AC39: =COUNTIFS(NPS관리활동_RAW!$D:$D, "고객센터", NPS관리활동_RAW!$I:$I, F39, NPS관리활동_RAW!$K:$K, "배분") -> 0 | AG39: =SUM(AK39:AV39) -> 0 | AK39: =COUNTIFS(NPS관리활동_RAW!$D:$D, "고객센터", NPS관리활동_RAW!$I:$I, F39, NPS관리활동_RAW!$L:$L, "현행유지") -> 0 | AO39: =COUNTIFS(NPS관리활동_RAW!$D:$D, "고객센터", NPS관리활동_RAW!$I:$I, F39, NPS관리활동_RAW!$L:$L, "개선불가") -> 0 | AS39: =COUNTIFS(NPS관리활동_RAW!$D:$D, "고객센터", NPS관리활동_RAW!$I:$I, F39, NPS관리활동_RAW!$L:$L, "개선예정") -> 0 | AW39: =IFERROR(AG39/AC39,0) -> 0
F40: 기타 | M40: =SUM(Q40:AB40) -> 0 | Q40: =SUM(COUNTIFS(NPS관리활동_RAW!$D:$D, $B$39, NPS관리활동_RAW!$G:$G, "긍정")) - SUM(COUNTIFS(NPS관리활동_RAW!$D:$D, $B$39, NPS관리활동_RAW!$I:$I, F39, NPS관리활동_RAW!$G:$G, "긍정")) -> 0 | U40: =SUM(COUNTIFS(NPS관리활동_RAW!$D:$D, $B$39, NPS관리활동_RAW!$G:$G, "부정")) - SUM(COUNTIFS(NPS관리활동_RAW!$D:$D, $B$39, NPS관리활동_RAW!$I:$I, F39, NPS관리활동_RAW!$G:$G, "부정")) -> 0 | Y40: =SUM(COUNTIFS(NPS관리활동_RAW!$D:$D, $B$39, NPS관리활동_RAW!$G:$G, "중립")) - SUM(COUNTIFS(NPS관리활동_RAW!$D:$D, $B$39, NPS관리활동_RAW!$I:$I, F39, NPS관리활동_RAW!$G:$G, "중립")) -> 0 | AC40: =COUNTIFS(NPS관리활동_RAW!$D:$D, "고객센터", NPS관리활동_RAW!$I:$I, "<>고객컨택영업그룹", NPS관리활동_RAW!$K:$K, "배분") -> 0 | AG40: =SUM(AK40:AV40) -> 0 | AK40: =SUM(COUNTIFS(NPS관리활동_RAW!$D:$D, B39, NPS관리활동_RAW!$L:$L, "현행유지")) - SUM(COUNTIFS(NPS관리활동_RAW!$D:$D, B39, NPS관리활동_RAW!$I:$I, F39, NPS관리활동_RAW!$L:$L, "현행유지")) -> 0 | AO40: =SUM(COUNTIFS(NPS관리활동_RAW!$D:$D, B39, NPS관리활동_RAW!$L:$L, "개선불가")) - SUM(COUNTIFS(NPS관리활동_RAW!$D:$D, B39, NPS관리활동_RAW!$I:$I, F39, NPS관리활동_RAW!$L:$L, "개선불가")) -> 0 | AS40: =SUM(COUNTIFS(NPS관리활동_RAW!$D:$D, B39, NPS관리활동_RAW!$L:$L, "개선예정")) - SUM(COUNTIFS(NPS관리활동_RAW!$D:$D, B39, NPS관리활동_RAW!$I:$I, F39, NPS관리활동_RAW!$L:$L, "개선예정")) -> 0 | AW40: =IFERROR(AG40/AC40,0) -> 0
F41: 소계 | M41: =SUM(M39:P40) -> 0 | Q41: =SUM(Q39:T40) -> 0 | U41: =SUM(U39:X40) -> 0 | Y41: =SUM(Y39:AB40) -> 0 | AC41: =SUM(AC39:AF40) -> 0 | AG41: =SUM(AG39:AJ40) -> 0 | AK41: =SUM(AK39:AN40) -> 0 | AO41: =SUM(AO39:AR40) -> 0 | AS41: =SUM(AS39:AV40) -> 0 | AW41: =IFERROR(AG41/AC41,0) -> 0
B42: 상품 | F42: 개인고객그룹 | M42: =SUM(Q42:AB42) -> 0 | Q42: =COUNTIFS(NPS관리활동_RAW!$D:$D, $B$42, NPS관리활동_RAW!$I:$I, $F42, NPS관리활동_RAW!$G:$G, "긍정") -> 0 | U42: =COUNTIFS(NPS관리활동_RAW!$D:$D, $B$42, NPS관리활동_RAW!$I:$I, $F42, NPS관리활동_RAW!$G:$G, "부정") -> 0 | Y42: =COUNTIFS(NPS관리활동_RAW!$D:$D, $B$42, NPS관리활동_RAW!$I:$I, $F42, NPS관리활동_RAW!$G:$G, "중립") -> 0 | AC42: =COUNTIFS(NPS관리활동_RAW!$D:$D, B42, NPS관리활동_RAW!$I:$I, F42, NPS관리활동_RAW!$K:$K, "배분") -> 0 | AG42: =SUM(AK42:AV42) -> 0 | AK42: =COUNTIFS(NPS관리활동_RAW!$D:$D, B42, NPS관리활동_RAW!$I:$I, F42, NPS관리활동_RAW!$L:$L, "현행유지") -> 0 | AO42: =COUNTIFS(NPS관리활동_RAW!$D:$D, B42, NPS관리활동_RAW!$I:$I, F42, NPS관리활동_RAW!$L:$L, "개선불가") -> 0 | AS42: =COUNTIFS(NPS관리활동_RAW!$D:$D, B42, NPS관리활동_RAW!$I:$I, F42, NPS관리활동_RAW!$L:$L, "개선예정") -> 0 | AW42: =IFERROR(AG42/AC42,0) -> 0
F43: WM고객그룹 | M43: =SUM(Q43:AB43) -> 0 | Q43: =COUNTIFS(NPS관리활동_RAW!$D:$D, $B$42, NPS관리활동_RAW!$I:$I, $F43, NPS관리활동_RAW!$G:$G, "긍정") -> 0 | U43: =COUNTIFS(NPS관리활동_RAW!$D:$D, $B$42, NPS관리활동_RAW!$I:$I, $F43, NPS관리활동_RAW!$G:$G, "부정") -> 0 | Y43: =COUNTIFS(NPS관리활동_RAW!$D:$D, $B$42, NPS관리활동_RAW!$I:$I, $F43, NPS관리활동_RAW!$G:$G, "중립") -> 0 | AC43: =COUNTIFS(NPS관리활동_RAW!$D:$D, B42, NPS관리활동_RAW!$I:$I, F43, NPS관리활동_RAW!$K:$K, "배분") -> 0 | AG43: =SUM(AK43:AV43) -> 0 | AK43: =COUNTIFS(NPS관리활동_RAW!$D:$D, B42, NPS관리활동_RAW!$I:$I, F43, NPS관리활동_RAW!$L:$L, "현행유지") -> 0 | AO43: =COUNTIFS(NPS관리활동_RAW!$D:$D, B42, NPS관리활동_RAW!$I:$I, F43, NPS관리활동_RAW!$L:$L, "개선불가") -> 0 | AS43: =COUNTIFS(NPS관리활동_RAW!$D:$D, B42, NPS관리활동_RAW!$I:$I, F43, NPS관리활동_RAW!$L:$L, "개선예정") -> 0 | AW43: =IFERROR(AG43/AC43,0) -> 0
F44: 기업고객그룹 | M44: =SUM(Q44:AB44) -> 0 | Q44: =COUNTIFS(NPS관리활동_RAW!$D:$D, $B$42, NPS관리활동_RAW!$I:$I, $F44, NPS관리활동_RAW!$G:$G, "긍정") -> 0 | U44: =COUNTIFS(NPS관리활동_RAW!$D:$D, $B$42, NPS관리활동_RAW!$I:$I, $F44, NPS관리활동_RAW!$G:$G, "부정") -> 0 | Y44: =COUNTIFS(NPS관리활동_RAW!$D:$D, $B$42, NPS관리활동_RAW!$I:$I, $F44, NPS관리활동_RAW!$G:$G, "중립") -> 0 | AC44: =COUNTIFS(NPS관리활동_RAW!$D:$D, B42, NPS관리활동_RAW!$I:$I, F44, NPS관리활동_RAW!$K:$K, "배분") -> 0 | AG44: =SUM(AK44:AV44) -> 0 | AK44: =COUNTIFS(NPS관리활동_RAW!$D:$D, B42, NPS관리활동_RAW!$I:$I, F44, NPS관리활동_RAW!$L:$L, "현행유지") -> 0 | AO44: =COUNTIFS(NPS관리활동_RAW!$D:$D, B42, NPS관리활동_RAW!$I:$I, F44, NPS관리활동_RAW!$L:$L, "개선불가") -> 0 | AS44: =COUNTIFS(NPS관리활동_RAW!$D:$D, B42, NPS관리활동_RAW!$I:$I, F44, NPS관리활동_RAW!$L:$L, "개선예정") -> 0 | AW44: =IFERROR(AG44/AC44,0) -> 0
F45: 기타 | M45: =SUM(Q45:AB45) -> 0 | Q45: {=SUM(COUNTIFS(NPS관리활동_RAW!$D:$D, $B$42, NPS관리활동_RAW!$G:$G, "긍정")) - SUM(COUNTIFS(NPS관리활동_RAW!$D:$D, $B$42, NPS관리활동_RAW!$I:$I, F42:F44, NPS관리활동_RAW!$G:$G, "긍정"))} -> 0 | U45: {=SUM(COUNTIFS(NPS관리활동_RAW!$D:$D, $B$42, NPS관리활동_RAW!$G:$G, "부정")) - SUM(COUNTIFS(NPS관리활동_RAW!$D:$D, $B$42, NPS관리활동_RAW!$I:$I, F42:F44, NPS관리활동_RAW!$G:$G, "부정"))} -> 0 | Y45: {=SUM(COUNTIFS(NPS관리활동_RAW!$D:$D, $B$42, NPS관리활동_RAW!$G:$G, "중립")) - SUM(COUNTIFS(NPS관리활동_RAW!$D:$D, $B$42, NPS관리활동_RAW!$I:$I, F42:F44, NPS관리활동_RAW!$G:$G, "중립"))} -> 0 | AC45: =COUNTIFS(NPS관리활동_RAW!$D:$D, B42, NPS관리활동_RAW!$I:$I, "<>개인고객그룹", NPS관리활동_RAW!$I:$I, "<>WM고객그룹", NPS관리활동_RAW!$I:$I, "<>기업고객그룹", NPS관리활동_RAW!$K:$K, "배분") -> 0 | AG45: =SUM(AK45:AV45) -> 0 | AK45: {=SUM(COUNTIFS(NPS관리활동_RAW!$D:$D, B42, NPS관리활동_RAW!$L:$L, "현행유지")) - SUM(COUNTIFS(NPS관리활동_RAW!$D:$D, B42, NPS관리활동_RAW!$I:$I, F42:F44, NPS관리활동_RAW!$L:$L, "현행유지"))} -> 0 | AO45: {=SUM(COUNTIFS(NPS관리활동_RAW!$D:$D, B42, NPS관리활동_RAW!$L:$L, "개선불가")) - SUM(COUNTIFS(NPS관리활동_RAW!$D:$D, B42, NPS관리활동_RAW!$I:$I, F42:F44, NPS관리활동_RAW!$L:$L, "개선불가"))} -> 0 | AS45: {=SUM(COUNTIFS(NPS관리활동_RAW!$D:$D, B42, NPS관리활동_RAW!$L:$L, "개선예정")) - SUM(COUNTIFS(NPS관리활동_RAW!$D:$D, B42, NPS관리활동_RAW!$I:$I, F42:F44, NPS관리활동_RAW!$L:$L, "개선예정"))} -> 0 | AW45: =IFERROR(AG45/AC45,0) -> 0
F46: 소계 | M46: =SUM(M42:P45) -> 0 | Q46: =SUM(Q42:T45) -> 0 | U46: =SUM(U42:X45) -> 0 | Y46: =SUM(Y42:AB45) -> 0 | AC46: =SUM(AC42:AF45) -> 0 | AG46: =SUM(AG42:AJ45) -> 0 | AK46: =SUM(AK42:AN45) -> 0 | AO46: =SUM(AO42:AR45) -> 0 | AS46: =SUM(AS42:AV45) -> 0 | AW46: =IFERROR(AG46/AC46,0) -> 0
B47: 합계 | M47: =SUM(M35,M38,M41,M46) -> 0 | Q47: =SUM(Q35,Q38,Q41,Q46) -> 0 | U47: =SUM(U35,U38,U41,U46) -> 0 | Y47: =SUM(Y35,Y38,Y41,Y46) -> 0 | AC47: =SUM(AC35,AC38,AC41,AC46) -> 0 | AG47: =SUM(AG35,AG38,AG41,AG46) -> 0 | AK47: =SUM(AK35,AK38,AK41,AK46) -> 0 | AO47: =SUM(AO35,AO38,AO41,AO46) -> 0 | AS47: =SUM(AS35,AS38,AS41,AS46) -> 0 | AW47: =IFERROR(AG47/AC47,0) -> 0
B49: ※ 설문진행 현황 및 VOC 관리활동 지표는 {{cm_yyyy}}년 {{cx_mm}}월 조사 건부터 집계
B51: ■ 고객경험단계별 NPS
B53: 스타뱅킹 | P53: 영업점 | AD53: 고객센터 | AR53: 상품
B54: 고객경험단계 | I54: NPS | L54: 전주대비 | P54: 고객경험단계 | W54: NPS | Z54: 전주대비 | AD54: 고객경험단계 | AK54: NPS | AN54: 전주대비 | AR54: 고객경험단계 | AY54: NPS | BB54: 전주대비
B55: 로그인/인증 | I55: {=SUMPRODUCT((고객경험단계별NPS_RAW!$A:$A="KB 스타뱅킹") * (고객경험단계별NPS_RAW!$B:$B=TRIM(B55)) * IFERROR(--고객경험단계별NPS_RAW!$C:$C,0))} -> 0 | L55: {=SUMPRODUCT((고객경험단계별NPS_RAW!$A:$A="KB 스타뱅킹") * (고객경험단계별NPS_RAW!$B:$B=TRIM(B55)) * IFERROR(--고객경험단계별NPS_RAW!$D:$D,0))} -> 0 | P55: 내점/방문 | W55: {=SUMPRODUCT((고객경험단계별NPS_RAW!$A:$A=TRIM(P$53)) * (고객경험단계별NPS_RAW!$B:$B=TRIM(P55)) * IFERROR(--고객경험단계별NPS_RAW!$C:$C,0))} -> 0 | Z55: {=SUMPRODUCT((고객경험단계별NPS_RAW!$A:$A=TRIM(P$53)) * (고객경험단계별NPS_RAW!$B:$B=TRIM(P55)) * IFERROR(--고객경험단계별NPS_RAW!$D:$D,0))} -> 0 | AD55: 버튼식ARS | AK55: {=SUMPRODUCT((고객경험단계별NPS_RAW!$A:$A=TRIM(AD$53)) * (고객경험단계별NPS_RAW!$B:$B=TRIM(AD55)) * IFERROR(--고객경험단계별NPS_RAW!$C:$C,0))} -> 0 | AN55: {=SUMPRODUCT((고객경험단계별NPS_RAW!$A:$A=TRIM(AD$53)) * (고객경험단계별NPS_RAW!$B:$B=TRIM(AD55)) * IFERROR(--고객경험단계별NPS_RAW!$D:$D,0))} -> 0 | AR55: 저축성 | AY55: {=SUMPRODUCT((고객경험단계별NPS_RAW!$A:$A=TRIM(AR$53)) * (고객경험단계별NPS_RAW!$B:$B=TRIM(AR55)) * IFERROR(--고객경험단계별NPS_RAW!$C:$C,0))} -> 0 | BB55: {=SUMPRODUCT((고객경험단계별NPS_RAW!$A:$A=TRIM(AR$53)) * (고객경험단계별NPS_RAW!$B:$B=TRIM(AR55)) * IFERROR(--고객경험단계별NPS_RAW!$D:$D,0))} -> 0
B56: 홈화면 | I56: {=SUMPRODUCT((고객경험단계별NPS_RAW!$A:$A="KB 스타뱅킹") * (고객경험단계별NPS_RAW!$B:$B=TRIM(B56)) * IFERROR(--고객경험단계별NPS_RAW!$C:$C,0))} -> 0 | L56: {=SUMPRODUCT((고객경험단계별NPS_RAW!$A:$A="KB 스타뱅킹") * (고객경험단계별NPS_RAW!$B:$B=TRIM(B56)) * IFERROR(--고객경험단계별NPS_RAW!$D:$D,0))} -> 0 | P56: 대기 | W56: {=SUMPRODUCT((고객경험단계별NPS_RAW!$A:$A=TRIM(P$53)) * (고객경험단계별NPS_RAW!$B:$B=TRIM(P56)) * IFERROR(--고객경험단계별NPS_RAW!$C:$C,0))} -> 0 | Z56: {=SUMPRODUCT((고객경험단계별NPS_RAW!$A:$A=TRIM(P$53)) * (고객경험단계별NPS_RAW!$B:$B=TRIM(P56)) * IFERROR(--고객경험단계별NPS_RAW!$D:$D,0))} -> 0 | AD56: 보이는ARS | AK56: {=SUMPRODUCT((고객경험단계별NPS_RAW!$A:$A=TRIM(AD$53)) * (고객경험단계별NPS_RAW!$B:$B=TRIM(AD56)) * IFERROR(--고객경험단계별NPS_RAW!$C:$C,0))} -> 0 | AN56: {=SUMPRODUCT((고객경험단계별NPS_RAW!$A:$A=TRIM(AD$53)) * (고객경험단계별NPS_RAW!$B:$B=TRIM(AD56)) * IFERROR(--고객경험단계별NPS_RAW!$D:$D,0))} -> 0 | AR56: 여신성 | AY56: {=SUMPRODUCT((고객경험단계별NPS_RAW!$A:$A=TRIM(AR$53)) * (고객경험단계별NPS_RAW!$B:$B=TRIM(AR56)) * IFERROR(--고객경험단계별NPS_RAW!$C:$C,0))} -> 0 | BB56: {=SUMPRODUCT((고객경험단계별NPS_RAW!$A:$A=TRIM(AR$53)) * (고객경험단계별NPS_RAW!$B:$B=TRIM(AR56)) * IFERROR(--고객경험단계별NPS_RAW!$D:$D,0))} -> 0
B57: 계좌조회/이체 | I57: {=SUMPRODUCT((고객경험단계별NPS_RAW!$A:$A="KB 스타뱅킹") * (고객경험단계별NPS_RAW!$B:$B=TRIM(B57)) * IFERROR(--고객경험단계별NPS_RAW!$C:$C,0))} -> 0 | L57: {=SUMPRODUCT((고객경험단계별NPS_RAW!$A:$A="KB 스타뱅킹") * (고객경험단계별NPS_RAW!$B:$B=TRIM(B57)) * IFERROR(--고객경험단계별NPS_RAW!$D:$D,0))} -> 0 | P57: 맞이/의도파악 | W57: {=SUMPRODUCT((고객경험단계별NPS_RAW!$A:$A=TRIM(P$53)) * (고객경험단계별NPS_RAW!$B:$B=TRIM(P57)) * IFERROR(--고객경험단계별NPS_RAW!$C:$C,0))} -> 0 | Z57: {=SUMPRODUCT((고객경험단계별NPS_RAW!$A:$A=TRIM(P$53)) * (고객경험단계별NPS_RAW!$B:$B=TRIM(P57)) * IFERROR(--고객경험단계별NPS_RAW!$D:$D,0))} -> 0 | AD57: 대기 | AK57: {=SUMPRODUCT((고객경험단계별NPS_RAW!$A:$A=TRIM(AD$53)) * (고객경험단계별NPS_RAW!$B:$B=TRIM(AD57)) * IFERROR(--고객경험단계별NPS_RAW!$C:$C,0))} -> 0 | AN57: {=SUMPRODUCT((고객경험단계별NPS_RAW!$A:$A=TRIM(AD$53)) * (고객경험단계별NPS_RAW!$B:$B=TRIM(AD57)) * IFERROR(--고객경험단계별NPS_RAW!$D:$D,0))} -> 0 | AR57: 투자성 | AY57: {=SUMPRODUCT((고객경험단계별NPS_RAW!$A:$A=TRIM(AR$53)) * (고객경험단계별NPS_RAW!$B:$B=TRIM(AR57)) * IFERROR(--고객경험단계별NPS_RAW!$C:$C,0))} -> 0 | BB57: {=SUMPRODUCT((고객경험단계별NPS_RAW!$A:$A=TRIM(AR$53)) * (고객경험단계별NPS_RAW!$B:$B=TRIM(AR57)) * IFERROR(--고객경험단계별NPS_RAW!$D:$D,0))} -> 0
B58: 통합검색 | I58: {=SUMPRODUCT((고객경험단계별NPS_RAW!$A:$A="KB 스타뱅킹") * (고객경험단계별NPS_RAW!$B:$B=TRIM(B58)) * IFERROR(--고객경험단계별NPS_RAW!$C:$C,0))} -> 0 | L58: {=SUMPRODUCT((고객경험단계별NPS_RAW!$A:$A="KB 스타뱅킹") * (고객경험단계별NPS_RAW!$B:$B=TRIM(B58)) * IFERROR(--고객경험단계별NPS_RAW!$D:$D,0))} -> 0 | P58: 직원상담 | W58: {=SUMPRODUCT((고객경험단계별NPS_RAW!$A:$A=TRIM(P$53)) * (고객경험단계별NPS_RAW!$B:$B=TRIM(P58)) * IFERROR(--고객경험단계별NPS_RAW!$C:$C,0))} -> 0 | Z58: {=SUMPRODUCT((고객경험단계별NPS_RAW!$A:$A=TRIM(P$53)) * (고객경험단계별NPS_RAW!$B:$B=TRIM(P58)) * IFERROR(--고객경험단계별NPS_RAW!$D:$D,0))} -> 0 | AD58: 챗봇상담 | AK58: {=SUMPRODUCT((고객경험단계별NPS_RAW!$A:$A=TRIM(AD$53)) * (고객경험단계별NPS_RAW!$B:$B=TRIM(AD58)) * IFERROR(--고객경험단계별NPS_RAW!$C:$C,0))} -> 0 | AN58: {=SUMPRODUCT((고객경험단계별NPS_RAW!$A:$A=TRIM(AD$53)) * (고객경험단계별NPS_RAW!$B:$B=TRIM(AD58)) * IFERROR(--고객경험단계별NPS_RAW!$D:$D,0))} -> 0 | AR58: 보장성 | AY58: {=SUMPRODUCT((고객경험단계별NPS_RAW!$A:$A=TRIM(AR$53)) * (고객경험단계별NPS_RAW!$B:$B=TRIM(AR58)) * IFERROR(--고객경험단계별NPS_RAW!$C:$C,0))} -> 0 | BB58: {=SUMPRODUCT((고객경험단계별NPS_RAW!$A:$A=TRIM(AR$53)) * (고객경험단계별NPS_RAW!$B:$B=TRIM(AR58)) * IFERROR(--고객경험단계별NPS_RAW!$D:$D,0))} -> 0
...

Sheet 2.NSS,CCI대시보드
B2: | 고객감정지수 및 고객불만지수 대시보드 | BD2: {{cm_yyyymmdd}}
B4: ■ 고객감정지수(NSS, Net Sentiment Score)
B6: - 고객감정지수가 50점 이상일 경우 긍정적인 감정이 우세하며, 0점 이하로 떨어질 경우 부정적 감정이 증가하는 신호로 해석
B7: - {{S2_script1}}
C10: 종합 NSS | N10: 스타뱅킹 NSS | Y10: 영업점 NSS | AJ10: 고객센터NSS | AU10: 상품 NSS
D12: =(IFERROR(COUNTIFS(NPS관리활동_RAW!$G:$G, "*긍정*"),0)-IFERROR(COUNTIFS(NPS관리활동_RAW!$G:$G, "*부정*"),0))/IFERROR(COUNTA(NPS관리활동_RAW!$D:$D), 1)*100 -> #DIV/0! | O12: =I42 -> #DIV/0! | W12: {{S2_NSS_2}} | Z12: =I51 -> #DIV/0! | AH12: {{S2_NSS_3}} | AK12: =I57 -> #DIV/0! | AS12: {{S2_NSS_4}} | AV12: =I64 -> #DIV/0! | BD12: {{S2_NSS_5}}
C14: 전주 대비 | I14: {=ROUND(D12-(SUMPRODUCT(--(NPS관리활동_RAW!A:A<=$BH$43)*(NPS관리활동_RAW!$G:$G="긍정"))-SUMPRODUCT(--(NPS관리활동_RAW!A:A<=$BH$43)*(NPS관리활동_RAW!$G:$G="부정")))/SUMPRODUCT(--(NPS관리활동_RAW!A:A<=$BH$43)*(NPS관리활동_RAW!A:A <>""))*100,1)} -> #DIV/0! | N14: 전주 대비 | T14: =O42 -> #DIV/0! | Y14: 전주 대비 | AE14: =O51 -> #DIV/0! | AJ14: 전주 대비 | AP14: =O57 -> #DIV/0! | AU14: 전주 대비 | BA14: =O64 -> #DIV/0!
C15: 전월 대비 | I15: {=ROUND(D12-(SUMPRODUCT(--(NPS관리활동_RAW!A:A<=$BH$44)*(NPS관리활동_RAW!$G:$G="긍정"))-SUMPRODUCT(--(NPS관리활동_RAW!A:A<=$BH$44)*(NPS관리활동_RAW!$G:$G="부정")))/SUMPRODUCT(--(NPS관리활동_RAW!A:A<=$BH$44)*(NPS관리활동_RAW!A:A <>""))*100,1)} -> #DIV/0! | N15: 전월 대비 | T15: {=ROUND(O12-(SUMPRODUCT(--(NPS관리활동_RAW!A:A<=$BH$44)*(NPS관리활동_RAW!$D:$D="KB 스타뱅킹")*(NPS관리활동_RAW!$G:$G="긍정"))-SUMPRODUCT(--(NPS관리활동_RAW!A:A<=$BH$44)*(NPS관리활동_RAW!$D:$D="KB 스타뱅킹")*(NPS관리활동_RAW!$G:$G="부정")))/SUMPRODUCT(--(NPS관리활동_RAW!A:A<=$BH$44)*(NPS관리활동_RAW!$D:$D="KB 스타뱅킹"))*100,1)} -> #DIV/0! | Y15: 전월 대비 | AE15: {=ROUND(Z12-(SUMPRODUCT(--(NPS관리활동_RAW!A:A<=$BH$44)*(NPS관리활동_RAW!$D:$D="영업점")*(NPS관리활동_RAW!$G:$G="긍정"))-SUMPRODUCT(--(NPS관리활동_RAW!A:A<=$BH$44)*(NPS관리활동_RAW!$D:$D="영업점")*(NPS관리활동_RAW!$G:$G="부정")))/SUMPRODUCT(--(NPS관리활동_RAW!A:A<=$BH$44)*(NPS관리활동_RAW!$D:$D="영업점"))*100,1)} -> #DIV/0! | AJ15: 전월 대비 | AP15: {=ROUND(AK12-(SUMPRODUCT(--(NPS관리활동_RAW!A:A<=$BH$44)*(NPS관리활동_RAW!$D:$D="고객센터")*(NPS관리활동_RAW!$G:$G="긍정"))-SUMPRODUCT(--(NPS관리활동_RAW!A:A<=$BH$44)*(NPS관리활동_RAW!$D:$D="고객센터")*(NPS관리활동_RAW!$G:$G="부정")))/SUMPRODUCT(--(NPS관리활동_RAW!A:A<=$BH$44)*(NPS관리활동_RAW!$D:$D="고객센터"))*100,1)} -> #DIV/0! | AU15: 전월 대비 | BA15: {=ROUND(AV12-(SUMPRODUCT(--(NPS관리활동_RAW!A:A<=$BH$44)*(NPS관리활동_RAW!$D:$D="상품")*(NPS관리활동_RAW!$G:$G="긍정"))-SUMPRODUCT(--(NPS관리활동_RAW!A:A<=$BH$44)*(NPS관리활동_RAW!$D:$D="상품")*(NPS관리활동_RAW!$G:$G="부정")))/SUMPRODUCT(--(NPS관리활동_RAW!A:A<=$BH$44)*(NPS관리활동_RAW!$D:$D="상품"))*100,1)} -> #DIV/0!
B18: ※ 고객감정지수(점) = (인입 VOC 중 감정 분류가 '긍정'인 VOC 비율) - (인입 VOC 중 감정 분류가 '부정'인 VOC 비율)
B21: ■ 고객불만지수(CCI, Customer Complaint Index)
B23: - 고객불만지수가 높을수록 고객 불만이 증가하고 있음을 의미하며, 10점 이하일 경우 일반적인 수준이나, 10점을 초과하면 관리가 필요한 상황
B24: - {{S2_script2}}
C27: 종합 CCI | N27: 스타뱅킹 CCI | Y27: 영업점 CCI | AJ27: 고객센터CCI | AU27: 상품 CCI
D29: =IFERROR(COUNTIF(NPS관리활동_RAW!$H:$H, "*불만*"),0)/IFERROR(COUNTA(NPS관리활동_RAW!$D:$D), 1) * 100 -> #DIV/0! | O29: =AG42 -> #DIV/0! | W29: {{S2_CCI_2}} | Z29: =AG51 -> #DIV/0! | AH29: {{S2_CCI_3}} | AK29: =AG57 -> #DIV/0! | AS29: {{S2_CCI_4}} | AV29: =AG64 -> #DIV/0! | BD29: {{S2_CCI_5}}
C31: 전주 대비 | I31: {=ROUND(D29-(SUMPRODUCT(--(NPS관리활동_RAW!A:A<=$BH$43)*(NPS관리활동_RAW!$H:$H="불만"))/SUMPRODUCT(--(NPS관리활동_RAW!A:A<=$BH$43)*(NPS관리활동_RAW!A:A <>""))*100), 1)} -> #DIV/0! | N31: 전주 대비 | T31: =AM42 -> #DIV/0! | Y31: 전주 대비 | AE31: =AM51 -> #DIV/0! | AJ31: 전주 대비 | AP31: =AM57 -> #DIV/0! | AU31: 전주 대비 | BA31: =AM64 -> #DIV/0!
C32: 전월 대비 | I32: {=ROUND(D29-(SUMPRODUCT(--(NPS관리활동_RAW!A:A<=$BH$44)*(NPS관리활동_RAW!$H:$H="불만"))/SUMPRODUCT(--(NPS관리활동_RAW!A:A<=$BH$44)*(NPS관리활동_RAW!A:A <>""))*100),1)} -> #DIV/0! | N32: 전월 대비 | T32: {=ROUND(AG42-(SUMPRODUCT(--(NPS관리활동_RAW!A:A<=$BH$44)*(NPS관리활동_RAW!$D:$D="KB 스타뱅킹")*(NPS관리활동_RAW!$H:$H="불만"))/SUMPRODUCT(--(NPS관리활동_RAW!A:A<=$BH$44)*(NPS관리활동_RAW!$D:$D="KB 스타뱅킹"))*100),1)} -> #DIV/0! | Y32: 전월 대비 | AE32: {=ROUND(AG51-(SUMPRODUCT(--(NPS관리활동_RAW!A:A<=$BH$44)*(NPS관리활동_RAW!$D:$D="영업점")*(NPS관리활동_RAW!$H:$H="불만"))/SUMPRODUCT(--(NPS관리활동_RAW!A:A<=$BH$44)*(NPS관리활동_RAW!$D:$D="영업점"))*100),1)} -> #DIV/0! | AJ32: 전월 대비 | AP32: {=ROUND(AG57-(SUMPRODUCT(--(NPS관리활동_RAW!A:A<=$BH$44)*(NPS관리활동_RAW!$D:$D="고객센터")*(NPS관리활동_RAW!$H:$H="불만"))/SUMPRODUCT(--(NPS관리활동_RAW!A:A<=$BH$44)*(NPS관리활동_RAW!$D:$D="고객센터"))*100),1)} -> #DIV/0! | AU32: 전월 대비 | BA32: {=ROUND(AG64-(SUMPRODUCT(--(NPS관리활동_RAW!A:A<=$BH$44)*(NPS관리활동_RAW!$D:$D="상품")*(NPS관리활동_RAW!$H:$H="불만"))/SUMPRODUCT(--(NPS관리활동_RAW!A:A<=$BH$44)*(NPS관리활동_RAW!$D:$D="상품"))*100),1)} -> #DIV/0!
B35: ※ 고객불만지수(점) = 인입 VOC 중 VOC 유형 분류가 '불만'인 VOC 비율
B38: ■ 고객경험단계별 고객감정지수 및 고객불만지수
B40: 구분 | I40: 고객감정지수 | AG40: 고객불만지수
B41: (단위 : 점, %) | O41: 전주 대비 | U41: 긍정 | AA41: 부정 | AM41: 전주 대비 | AS41: 칭찬 | AY41: 불만
B42: 스타뱅킹 | I42: =U42-AA42 -> #DIV/0! | O42: {=O12-(SUMPRODUCT(--(NPS관리활동_RAW!A:A<=$BH$43)*(NPS관리활동_RAW!$D:$D="KB 스타뱅킹")*(NPS관리활동_RAW!$G:$G="긍정"))-SUMPRODUCT(--(NPS관리활동_RAW!A:A<=$BH$43)*(NPS관리활동_RAW!$D:$D="KB 스타뱅킹")*(NPS관리활동_RAW!$G:$G="부정")))/SUMPRODUCT(--(NPS관리활동_RAW!A:A<=$BH$43)*(NPS관리활동_RAW!$D:$D="KB 스타뱅킹"))*100} -> #DIV/0! | U42: =IFERROR(COUNTIFS(NPS관리활동_RAW!$D:$D, "KB 스타뱅킹", NPS관리활동_RAW!$G:$G, "*긍정*"),0)/IFERROR(COUNTIFS(NPS관리활동_RAW!$D:$D, "KB 스타뱅킹"), 1) * 100 -> #DIV/0! | AA42: =IFERROR(COUNTIFS(NPS관리활동_RAW!$D:$D, "KB 스타뱅킹", NPS관리활동_RAW!$G:$G, "*부정*"),0)/IFERROR(COUNTIFS(NPS관리활동_RAW!$D:$D, "KB 스타뱅킹"), 1) * 100 -> #DIV/0! | AG42: =AY42 -> #DIV/0! | AM42: {=AG42-(SUMPRODUCT(--(NPS관리활동_RAW!A:A<=$BH$43)*(NPS관리활동_RAW!$D:$D="KB 스타뱅킹")*(NPS관리활동_RAW!$H:$H="불만"))/SUMPRODUCT(--(NPS관리활동_RAW!A:A<=$BH$43)*(NPS관리활동_RAW!$D:$D="KB 스타뱅킹"))*100)} -> #DIV/0! | AS42: =IFERROR(COUNTIFS(NPS관리활동_RAW!$D:$D, "KB 스타뱅킹", NPS관리활동_RAW!$H:$H, "*칭찬*"),0)/IFERROR(COUNTIFS(NPS관리활동_RAW!$D:$D, "KB 스타뱅킹"), 1) * 100 -> #DIV/0! | AY42: =IFERROR(COUNTIFS(NPS관리활동_RAW!$D:$D, "KB 스타뱅킹", NPS관리활동_RAW!$H:$H, "*불만*"),0)/IFERROR(COUNTIFS(NPS관리활동_RAW!$D:$D, "KB 스타뱅킹"), 1) * 100 -> #DIV/0! | BG42: 이번주 | BH42: {=MAX(VALUE(NPS관리활동_RAW!$A2:$A1000000))} -> 0
C43: 로그인/인증 | I43: =U43-AA43 -> 0 | O43: {=I43-(SUMPRODUCT(--(NPS관리활동_RAW!A:A<=$BH$43)*(NPS관리활동_RAW!$D:$D="KB 스타뱅킹")*(NPS관리활동_RAW!$E:$E=TRIM($C43))*(NPS관리활동_RAW!$G:$G="긍정"))-SUMPRODUCT(--(NPS관리활동_RAW!A:A<=$BH$43)*(NPS관리활동_RAW!$D:$D="KB 스타뱅킹")*(NPS관리활동_RAW!$E:$E=TRIM($C43))*(NPS관리활동_RAW!$G:$G="부정")))/SUMPRODUCT(--(NPS관리활동_RAW!A:A<=$BH$43)*(NPS관리활동_RAW!$D:$D="KB 스타뱅킹")*(NPS관리활동_RAW!$E:$E=TRIM($C43)))*100} -> #VALUE! | U43: =IFERROR(COUNTIFS(NPS관리활동_RAW!$D:$D, "KB 스타뱅킹", NPS관리활동_RAW!$E:$E, C43, NPS관리활동_RAW!$G:$G,"긍정")/COUNTIFS(NPS관리활동_RAW!$D:$D, "KB 스타뱅킹", NPS관리활동_RAW!$E:$E, C43)*100,0) -> 0 | AA43: =IFERROR(COUNTIFS(NPS관리활동_RAW!$D:$D, "KB 스타뱅킹", NPS관리활동_RAW!$E:$E, C43, NPS관리활동_RAW!$G:$G,"부정")/COUNTIFS(NPS관리활동_RAW!$D:$D, "KB 스타뱅킹", NPS관리활동_RAW!$E:$E, C43)*100,0) -> 0 | AG43: =AY43 -> 0 | AM43: {=AG43-(SUMPRODUCT(--(NPS관리활동_RAW!A:A<=$BH$43)*(NPS관리활동_RAW!$D:$D="KB 스타뱅킹")*(NPS관리활동_RAW!$E:$E=TRIM($C43))*(NPS관리활동_RAW!$H:$H="불만"))/SUMPRODUCT(--(NPS관리활동_RAW!A:A<=$BH$43)*(NPS관리활동_RAW!$D:$D="KB 스타뱅킹")*(NPS관리활동_RAW!$E:$E=TRIM($C43)))*100)} -> #VALUE! | AS43: =IFERROR(COUNTIFS(NPS관리활동_RAW!$D:$D, "KB 스타뱅킹", NPS관리활동_RAW!$E:$E, C43, NPS관리활동_RAW!$H:$H,"칭찬")/COUNTIFS(NPS관리활동_RAW!$D:$D, "KB 스타뱅킹", NPS관리활동_RAW!$E:$E, C43)*100,0) -> 0 | AY43: =IFERROR(COUNTIFS(NPS관리활동_RAW!$D:$D, "KB 스타뱅킹", NPS관리활동_RAW!$E:$E, C43, NPS관리활동_RAW!$H:$H,"불만")/COUNTIFS(NPS관리활동_RAW!$D:$D, "KB 스타뱅킹", NPS관리활동_RAW!$E:$E, C43)*100,0) -> 0 | BG43: 전주 | BH43: =_xlfn.XLOOKUP(TEXT(DATE(LEFT(BH42,4), MID(BH42,5,2), RIGHT(BH42,2))-7, "yyyymmdd"), NPS관리활동_RAW!$A:$A, NPS관리활동_RAW!$A:$A, "없음", -1) -> #VALUE!
C44: 홈화면 | I44: =U44-AA44 -> 0 | O44: {=I44-(SUMPRODUCT(--(NPS관리활동_RAW!A:A<=$BH$43)*(NPS관리활동_RAW!$D:$D="KB 스타뱅킹")*(NPS관리활동_RAW!$E:$E=TRIM($C44))*(NPS관리활동_RAW!$G:$G="긍정"))-SUMPRODUCT(--(NPS관리활동_RAW!A:A<=$BH$43)*(NPS관리활동_RAW!$D:$D="KB 스타뱅킹")*(NPS관리활동_RAW!$E:$E=TRIM($C44))*(NPS관리활동_RAW!$G:$G="부정")))/SUMPRODUCT(--(NPS관리활동_RAW!A:A<=$BH$43)*(NPS관리활동_RAW!$D:$D="KB 스타뱅킹")*(NPS관리활동_RAW!$E:$E=TRIM($C44)))*100} -> #VALUE! | U44: =IFERROR(COUNTIFS(NPS관리활동_RAW!$D:$D, "KB 스타뱅킹", NPS관리활동_RAW!$E:$E, C44, NPS관리활동_RAW!$G:$G,"긍정")/COUNTIFS(NPS관리활동_RAW!$D:$D, "KB 스타뱅킹", NPS관리활동_RAW!$E:$E, C44)*100,0) -> 0 | AA44: =IFERROR(COUNTIFS(NPS관리활동_RAW!$D:$D, "KB 스타뱅킹", NPS관리활동_RAW!$E:$E, C44, NPS관리활동_RAW!$G:$G,"부정")/COUNTIFS(NPS관리활동_RAW!$D:$D, "KB 스타뱅킹", NPS관리활동_RAW!$E:$E, C44)*100,0) -> 0 | AG44: =AY44 -> 0 | AM44: {=AG44-(SUMPRODUCT(--(NPS관리활동_RAW!A:A<=$BH$43)*(NPS관리활동_RAW!$D:$D="KB 스타뱅킹")*(NPS관리활동_RAW!$E:$E=TRIM($C44))*(NPS관리활동_RAW!$H:$H="불만"))/SUMPRODUCT(--(NPS관리활동_RAW!A:A<=$BH$43)*(NPS관리활동_RAW!$D:$D="KB 스타뱅킹")*(NPS관리활동_RAW!$E:$E=TRIM($C44)))*100)} -> #VALUE! | AS44: =IFERROR(COUNTIFS(NPS관리활동_RAW!$D:$D, "KB 스타뱅킹", NPS관리활동_RAW!$E:$E, C44, NPS관리활동_RAW!$H:$H,"칭찬")/COUNTIFS(NPS관리활동_RAW!$D:$D, "KB 스타뱅킹", NPS관리활동_RAW!$E:$E, C44)*100,0) -> 0 | AY44: =IFERROR(COUNTIFS(NPS관리활동_RAW!$D:$D, "KB 스타뱅킹", NPS관리활동_RAW!$E:$E, C44, NPS관리활동_RAW!$H:$H,"불만")/COUNTIFS(NPS관리활동_RAW!$D:$D, "KB 스타뱅킹", NPS관리활동_RAW!$E:$E, C44)*100,0) -> 0 | BG44: 전월 | BH44: =_xlfn.XLOOKUP(TEXT(DATE(LEFT(BH42,4), MID(BH42,5,2), "01")-1, "yyyymmdd"), NPS관리활동_RAW!$A:$A, NPS관리활동_RAW!$A:$A, "없음", -1) -> #VALUE!
C45: 계좌조회/이체 | I45: =U45-AA45 -> 0 | O45: {=I45-(SUMPRODUCT(--(NPS관리활동_RAW!A:A<=$BH$43)*(NPS관리활동_RAW!$D:$D="KB 스타뱅킹")*(NPS관리활동_RAW!$E:$E=TRIM($C45))*(NPS관리활동_RAW!$G:$G="긍정"))-SUMPRODUCT(--(NPS관리활동_RAW!A:A<=$BH$43)*(NPS관리활동_RAW!$D:$D="KB 스타뱅킹")*(NPS관리활동_RAW!$E:$E=TRIM($C45))*(NPS관리활동_RAW!$G:$G="부정")))/SUMPRODUCT(--(NPS관리활동_RAW!A:A<=$BH$43)*(NPS관리활동_RAW!$D:$D="KB 스타뱅킹")*(NPS관리활동_RAW!$E:$E=TRIM($C45)))*100} -> #VALUE! | U45: =IFERROR(COUNTIFS(NPS관리활동_RAW!$D:$D, "KB 스타뱅킹", NPS관리활동_RAW!$E:$E, C45, NPS관리활동_RAW!$G:$G,"긍정")/COUNTIFS(NPS관리활동_RAW!$D:$D, "KB 스타뱅킹", NPS관리활동_RAW!$E:$E, C45)*100,0) -> 0 | AA45: =IFERROR(COUNTIFS(NPS관리활동_RAW!$D:$D, "KB 스타뱅킹", NPS관리활동_RAW!$E:$E, C45, NPS관리활동_RAW!$G:$G,"부정")/COUNTIFS(NPS관리활동_RAW!$D:$D, "KB 스타뱅킹", NPS관리활동_RAW!$E:$E, C45)*100,0) -> 0 | AG45: =AY45 -> 0 | AM45: {=AG45-(SUMPRODUCT(--(NPS관리활동_RAW!A:A<=$BH$43)*(NPS관리활동_RAW!$D:$D="KB 스타뱅킹")*(NPS관리활동_RAW!$E:$E=TRIM($C45))*(NPS관리활동_RAW!$H:$H="불만"))/SUMPRODUCT(--(NPS관리활동_RAW!A:A<=$BH$43)*(NPS관리활동_RAW!$D:$D="KB 스타뱅킹")*(NPS관리활동_RAW!$E:$E=TRIM($C45)))*100)} -> #VALUE! | AS45: =IFERROR(COUNTIFS(NPS관리활동_RAW!$D:$D, "KB 스타뱅킹", NPS관리활동_RAW!$E:$E, C45, NPS관리활동_RAW!$H:$H,"칭찬")/COUNTIFS(NPS관리활동_RAW!$D:$D, "KB 스타뱅킹", NPS관리활동_RAW!$E:$E, C45)*100,0) -> 0 | AY45: =IFERROR(COUNTIFS(NPS관리활동_RAW!$D:$D, "KB 스타뱅킹", NPS관리활동_RAW!$E:$E, C45, NPS관리활동_RAW!$H:$H,"불만")/COUNTIFS(NPS관리활동_RAW!$D:$D, "KB 스타뱅킹", NPS관리활동_RAW!$E:$E, C45)*100,0) -> 0
C46: 통합검색 | I46: =U46-AA46 -> 0 | O46: {=I46-(SUMPRODUCT(--(NPS관리활동_RAW!A:A<=$BH$43)*(NPS관리활동_RAW!$D:$D="KB 스타뱅킹")*(NPS관리활동_RAW!$E:$E=TRIM($C46))*(NPS관리활동_RAW!$G:$G="긍정"))-SUMPRODUCT(--(NPS관리활동_RAW!A:A<=$BH$43)*(NPS관리활동_RAW!$D:$D="KB 스타뱅킹")*(NPS관리활동_RAW!$E:$E=TRIM($C46))*(NPS관리활동_RAW!$G:$G="부정")))/SUMPRODUCT(--(NPS관리활동_RAW!A:A<=$BH$43)*(NPS관리활동_RAW!$D:$D="KB 스타뱅킹")*(NPS관리활동_RAW!$E:$E=TRIM($C46)))*100} -> #VALUE! | U46: =IFERROR(COUNTIFS(NPS관리활동_RAW!$D:$D, "KB 스타뱅킹", NPS관리활동_RAW!$E:$E, C46, NPS관리활동_RAW!$G:$G,"긍정")/COUNTIFS(NPS관리활동_RAW!$D:$D, "KB 스타뱅킹", NPS관리활동_RAW!$E:$E, C46)*100,0) -> 0 | AA46: =IFERROR(COUNTIFS(NPS관리활동_RAW!$D:$D, "KB 스타뱅킹", NPS관리활동_RAW!$E:$E, C46, NPS관리활동_RAW!$G:$G,"부정")/COUNTIFS(NPS관리활동_RAW!$D:$D, "KB 스타뱅킹", NPS관리활동_RAW!$E:$E, C46)*100,0) -> 0 | AG46: =AY46 -> 0 | AM46: {=AG46-(SUMPRODUCT(--(NPS관리활동_RAW!A:A<=$BH$43)*(NPS관리활동_RAW!$D:$D="KB 스타뱅킹")*(NPS관리활동_RAW!$E:$E=TRIM($C46))*(NPS관리활동_RAW!$H:$H="불만"))/SUMPRODUCT(--(NPS관리활동_RAW!A:A<=$BH$43)*(NPS관리활동_RAW!$D:$D="KB 스타뱅킹")*(NPS관리활동_RAW!$E:$E=TRIM($C46)))*100)} -> #VALUE! | AS46: =IFERROR(COUNTIFS(NPS관리활동_RAW!$D:$D, "KB 스타뱅킹", NPS관리활동_RAW!$E:$E, C46, NPS관리활동_RAW!$H:$H,"칭찬")/COUNTIFS(NPS관리활동_RAW!$D:$D, "KB 스타뱅킹", NPS관리활동_RAW!$E:$E, C46)*100,0) -> 0 | AY46: =IFERROR(COUNTIFS(NPS관리활동_RAW!$D:$D, "KB 스타뱅킹", NPS관리활동_RAW!$E:$E, C46, NPS관리활동_RAW!$H:$H,"불만")/COUNTIFS(NPS관리활동_RAW!$D:$D, "KB 스타뱅킹", NPS관리활동_RAW!$E:$E, C46)*100,0) -> 0
C47: 금융상품몰 | I47: =U47-AA47 -> 0 | O47: {=I47-(SUMPRODUCT(--(NPS관리활동_RAW!A:A<=$BH$43)*(NPS관리활동_RAW!$D:$D="KB 스타뱅킹")*(NPS관리활동_RAW!$E:$E=TRIM($C47))*(NPS관리활동_RAW!$G:$G="긍정"))-SUMPRODUCT(--(NPS관리활동_RAW!A:A<=$BH$43)*(NPS관리활동_RAW!$D:$D="KB 스타뱅킹")*(NPS관리활동_RAW!$E:$E=TRIM($C47))*(NPS관리활동_RAW!$G:$G="부정")))/SUMPRODUCT(--(NPS관리활동_RAW!A:A<=$BH$43)*(NPS관리활동_RAW!$D:$D="KB 스타뱅킹")*(NPS관리활동_RAW!$E:$E=TRIM($C47)))*100} -> #VALUE! | U47: =IFERROR(COUNTIFS(NPS관리활동_RAW!$D:$D, "KB 스타뱅킹", NPS관리활동_RAW!$E:$E, C47, NPS관리활동_RAW!$G:$G,"긍정")/COUNTIFS(NPS관리활동_RAW!$D:$D, "KB 스타뱅킹", NPS관리활동_RAW!$E:$E, C47)*100,0) -> 0 | AA47: =IFERROR(COUNTIFS(NPS관리활동_RAW!$D:$D, "KB 스타뱅킹", NPS관리활동_RAW!$E:$E, C47, NPS관리활동_RAW!$G:$G,"부정")/COUNTIFS(NPS관리활동_RAW!$D:$D, "KB 스타뱅킹", NPS관리활동_RAW!$E:$E, C47)*100,0) -> 0 | AG47: =AY47 -> 0 | AM47: {=AG47-(SUMPRODUCT(--(NPS관리활동_RAW!A:A<=$BH$43)*(NPS관리활동_RAW!$D:$D="KB 스타뱅킹")*(NPS관리활동_RAW!$E:$E=TRIM($C47))*(NPS관리활동_RAW!$H:$H="불만"))/SUMPRODUCT(--(NPS관리활동_RAW!A:A<=$BH$43)*(NPS관리활동_RAW!$D:$D="KB 스타뱅킹")*(NPS관리활동_RAW!$E:$E=TRIM($C47)))*100)} -> #VALUE! | AS47: =IFERROR(COUNTIFS(NPS관리활동_RAW!$D:$D, "KB 스타뱅킹", NPS관리활동_RAW!$E:$E, C47, NPS관리활동_RAW!$H:$H,"칭찬")/COUNTIFS(NPS관리활동_RAW!$D:$D, "KB 스타뱅킹", NPS관리활동_RAW!$E:$E, C47)*100,0) -> 0 | AY47: =IFERROR(COUNTIFS(NPS관리활동_RAW!$D:$D, "KB 스타뱅킹", NPS관리활동_RAW!$E:$E, C47, NPS관리활동_RAW!$H:$H,"불만")/COUNTIFS(NPS관리활동_RAW!$D:$D, "KB 스타뱅킹", NPS관리활동_RAW!$E:$E, C47)*100,0) -> 0
C48: 상품가입 | I48: =U48-AA48 -> 0 | O48: {=I48-(SUMPRODUCT(--(NPS관리활동_RAW!A:A<=$BH$43)*(NPS관리활동_RAW!$D:$D="KB 스타뱅킹")*(NPS관리활동_RAW!$E:$E=TRIM($C48))*(NPS관리활동_RAW!$G:$G="긍정"))-SUMPRODUCT(--(NPS관리활동_RAW!A:A<=$BH$43)*(NPS관리활동_RAW!$D:$D="KB 스타뱅킹")*(NPS관리활동_RAW!$E:$E=TRIM($C48))*(NPS관리활동_RAW!$G:$G="부정")))/SUMPRODUCT(--(NPS관리활동_RAW!A:A<=$BH$43)*(NPS관리활동_RAW!$D:$D="KB 스타뱅킹")*(NPS관리활동_RAW!$E:$E=TRIM($C48)))*100} -> #VALUE! | U48: =IFERROR(COUNTIFS(NPS관리활동_RAW!$D:$D, "KB 스타뱅킹", NPS관리활동_RAW!$E:$E, C48, NPS관리활동_RAW!$G:$G,"긍정")/COUNTIFS(NPS관리활동_RAW!$D:$D, "KB 스타뱅킹", NPS관리활동_RAW!$E:$E, C48)*100,0) -> 0 | AA48: =IFERROR(COUNTIFS(NPS관리활동_RAW!$D:$D, "KB 스타뱅킹", NPS관리활동_RAW!$E:$E, C48, NPS관리활동_RAW!$G:$G,"부정")/COUNTIFS(NPS관리활동_RAW!$D:$D, "KB 스타뱅킹", NPS관리활동_RAW!$E:$E, C48)*100,0) -> 0 | AG48: =AY48 -> 0 | AM48: {=AG48-(SUMPRODUCT(--(NPS관리활동_RAW!A:A<=$BH$43)*(NPS관리활동_RAW!$D:$D="KB 스타뱅킹")*(NPS관리활동_RAW!$E:$E=TRIM($C48))*(NPS관리활동_RAW!$H:$H="불만"))/SUMPRODUCT(--(NPS관리활동_RAW!A:A<=$BH$43)*(NPS관리활동_RAW!$D:$D="KB 스타뱅킹")*(NPS관리활동_RAW!$E:$E=TRIM($C48)))*100)} -> #VALUE! | AS48: =IFERROR(COUNTIFS(NPS관리활동_RAW!$D:$D, "KB 스타뱅킹", NPS관리활동_RAW!$E:$E, C48, NPS관리활동_RAW!$H:$H,"칭찬")/COUNTIFS(NPS관리활동_RAW!$D:$D, "KB 스타뱅킹", NPS관리활동_RAW!$E:$E, C48)*100,0) -> 0 | AY48: =IFERROR(COUNTIFS(NPS관리활동_RAW!$D:$D, "KB 스타뱅킹", NPS관리활동_RAW!$E:$E, C48, NPS관리활동_RAW!$H:$H,"불만")/COUNTIFS(NPS관리활동_RAW!$D:$D, "KB 스타뱅킹", NPS관리활동_RAW!$E:$E, C48)*100,0) -> 0
C49: 상품관리/해지 | I49: =U49-AA49 -> 0 | O49: {=I49-(SUMPRODUCT(--(NPS관리활동_RAW!A:A<=$BH$43)*(NPS관리활동_RAW!$D:$D="KB 스타뱅킹")*(NPS관리활동_RAW!$E:$E=TRIM($C49))*(NPS관리활동_RAW!$G:$G="긍정"))-SUMPRODUCT(--(NPS관리활동_RAW!A:A<=$BH$43)*(NPS관리활동_RAW!$D:$D="KB 스타뱅킹")*(NPS관리활동_RAW!$E:$E=TRIM($C49))*(NPS관리활동_RAW!$G:$G="부정")))/SUMPRODUCT(--(NPS관리활동_RAW!A:A<=$BH$43)*(NPS관리활동_RAW!$D:$D="KB 스타뱅킹")*(NPS관리활동_RAW!$E:$E=TRIM($C49)))*100} -> #VALUE! | U49: =IFERROR(COUNTIFS(NPS관리활동_RAW!$D:$D, "KB 스타뱅킹", NPS관리활동_RAW!$E:$E, C49, NPS관리활동_RAW!$G:$G,"긍정")/COUNTIFS(NPS관리활동_RAW!$D:$D, "KB 스타뱅킹", NPS관리활동_RAW!$E:$E, C49)*100,0) -> 0 | AA49: =IFERROR(COUNTIFS(NPS관리활동_RAW!$D:$D, "KB 스타뱅킹", NPS관리활동_RAW!$E:$E, C49, NPS관리활동_RAW!$G:$G,"부정")/COUNTIFS(NPS관리활동_RAW!$D:$D, "KB 스타뱅킹", NPS관리활동_RAW!$E:$E, C49)*100,0) -> 0 | AG49: =AY49 -> 0 | AM49: {=AG49-(SUMPRODUCT(--(NPS관리활동_RAW!A:A<=$BH$43)*(NPS관리활동_RAW!$D:$D="KB 스타뱅킹")*(NPS관리활동_RAW!$E:$E=TRIM($C49))*(NPS관리활동_RAW!$H:$H="불만"))/SUMPRODUCT(--(NPS관리활동_RAW!A:A<=$BH$43)*(NPS관리활동_RAW!$D:$D="KB 스타뱅킹")*(NPS관리활동_RAW!$E:$E=TRIM($C49)))*100)} -> #VALUE! | AS49: =IFERROR(COUNTIFS(NPS관리활동_RAW!$D:$D, "KB 스타뱅킹", NPS관리활동_RAW!$E:$E, C49, NPS관리활동_RAW!$H:$H,"칭찬")/COUNTIFS(NPS관리활동_RAW!$D:$D, "KB 스타뱅킹", NPS관리활동_RAW!$E:$E, C49)*100,0) -> 0 | AY49: =IFERROR(COUNTIFS(NPS관리활동_RAW!$D:$D, "KB 스타뱅킹", NPS관리활동_RAW!$E:$E, C49, NPS관리활동_RAW!$H:$H,"불만")/COUNTIFS(NPS관리활동_RAW!$D:$D, "KB 스타뱅킹", NPS관리활동_RAW!$E:$E, C49)*100,0) -> 0
C50: 콘텐츠/서비스 | I50: =U50-AA50 -> 0 | O50: {=I50-(SUMPRODUCT(--(NPS관리활동_RAW!A:A<=$BH$43)*(NPS관리활동_RAW!$D:$D="KB 스타뱅킹")*(NPS관리활동_RAW!$E:$E=TRIM($C50))*(NPS관리활동_RAW!$G:$G="긍정"))-SUMPRODUCT(--(NPS관리활동_RAW!A:A<=$BH$43)*(NPS관리활동_RAW!$D:$D="KB 스타뱅킹")*(NPS관리활동_RAW!$E:$E=TRIM($C50))*(NPS관리활동_RAW!$G:$G="부정")))/SUMPRODUCT(--(NPS관리활동_RAW!A:A<=$BH$43)*(NPS관리활동_RAW!$D:$D="KB 스타뱅킹")*(NPS관리활동_RAW!$E:$E=TRIM($C50)))*100} -> #VALUE! | U50: =IFERROR(COUNTIFS(NPS관리활동_RAW!$D:$D, "KB 스타뱅킹", NPS관리활동_RAW!$E:$E, C50, NPS관리활동_RAW!$G:$G,"긍정")/COUNTIFS(NPS관리활동_RAW!$D:$D, "KB 스타뱅킹", NPS관리활동_RAW!$E:$E, C50)*100,0) -> 0 | AA50: =IFERROR(COUNTIFS(NPS관리활동_RAW!$D:$D, "KB 스타뱅킹", NPS관리활동_RAW!$E:$E, C50, NPS관리활동_RAW!$G:$G,"부정")/COUNTIFS(NPS관리활동_RAW!$D:$D, "KB 스타뱅킹", NPS관리활동_RAW!$E:$E, C50)*100,0) -> 0 | AG50: =AY50 -> 0 | AM50: {=AG50-(SUMPRODUCT(--(NPS관리활동_RAW!A:A<=$BH$43)*(NPS관리활동_RAW!$D:$D="KB 스타뱅킹")*(NPS관리활동_RAW!$E:$E=TRIM($C50))*(NPS관리활동_RAW!$H:$H="불만"))/SUMPRODUCT(--(NPS관리활동_RAW!A:A<=$BH$43)*(NPS관리활동_RAW!$D:$D="KB 스타뱅킹")*(NPS관리활동_RAW!$E:$E=TRIM($C50)))*100)} -> #VALUE! | AS50: =IFERROR(COUNTIFS(NPS관리활동_RAW!$D:$D, "KB 스타뱅킹", NPS관리활동_RAW!$E:$E, C50, NPS관리활동_RAW!$H:$H,"칭찬")/COUNTIFS(NPS관리활동_RAW!$D:$D, "KB 스타뱅킹", NPS관리활동_RAW!$E:$E, C50)*100,0) -> 0 | AY50: =IFERROR(COUNTIFS(NPS관리활동_RAW!$D:$D, "KB 스타뱅킹", NPS관리활동_RAW!$E:$E, C50, NPS관리활동_RAW!$H:$H,"불만")/COUNTIFS(NPS관리활동_RAW!$D:$D, "KB 스타뱅킹", NPS관리활동_RAW!$E:$E, C50)*100,0) -> 0
B51: 영업점 | I51: =U51-AA51 -> #DIV/0! | O51: {=Z12-(SUMPRODUCT(--(NPS관리활동_RAW!A:A<=$BH$43)*(NPS관리활동_RAW!$D:$D="영업점")*(NPS관리활동_RAW!$G:$G="긍정"))-SUMPRODUCT(--(NPS관리활동_RAW!A:A<=$BH$43)*(NPS관리활동_RAW!$D:$D="영업점")*(NPS관리활동_RAW!$G:$G="부정")))/SUMPRODUCT(--(NPS관리활동_RAW!A:A<=$BH$43)*(NPS관리활동_RAW!$D:$D="영업점"))*100} -> #DIV/0! | U51: =IFERROR(COUNTIFS(NPS관리활동_RAW!$D:$D, TRIM(B51), NPS관리활동_RAW!$G:$G, "*긍정*"),0)/IFERROR(COUNTIFS(NPS관리활동_RAW!$D:$D, TRIM(B51)), 1) * 100 -> #DIV/0! | AA51: =IFERROR(COUNTIFS(NPS관리활동_RAW!$D:$D, TRIM(B51), NPS관리활동_RAW!$G:$G, "*부정*"),0)/IFERROR(COUNTIFS(NPS관리활동_RAW!$D:$D, TRIM(B51)), 1) * 100 -> #DIV/0! | AG51: =AY51 -> #DIV/0! | AM51: {=AG51-(SUMPRODUCT(--(NPS관리활동_RAW!A:A<=$BH$43)*(NPS관리활동_RAW!$D:$D="영업점")*(NPS관리활동_RAW!$H:$H="불만"))/SUMPRODUCT(--(NPS관리활동_RAW!A:A<=$BH$43)*(NPS관리활동_RAW!$D:$D="영업점"))*100)} -> #DIV/0! | AS51: =IFERROR(COUNTIFS(NPS관리활동_RAW!$D:$D, TRIM(B51), NPS관리활동_RAW!$H:$H, "*칭찬*"),0)/IFERROR(COUNTIFS(NPS관리활동_RAW!$D:$D, TRIM(B51)), 1) * 100 -> #DIV/0! | AY51: =IFERROR(COUNTIFS(NPS관리활동_RAW!$D:$D, TRIM(B51), NPS관리활동_RAW!$H:$H, "*불만*"),0)/IFERROR(COUNTIFS(NPS관리활동_RAW!$D:$D, TRIM(B51)), 1) * 100 -> #DIV/0!
C52: 내점/방문 | I52: =U52-AA52 -> 0 | O52: {=I52-(SUMPRODUCT(--(NPS관리활동_RAW!A:A<=$BH$43)*(NPS관리활동_RAW!$D:$D=$B$51)*(NPS관리활동_RAW!$E:$E=TRIM($C52))*(NPS관리활동_RAW!$G:$G="긍정"))-SUMPRODUCT(--(NPS관리활동_RAW!A:A<=$BH$43)*(NPS관리활동_RAW!$D:$D=$B$51)*(NPS관리활동_RAW!$E:$E=TRIM($C52))*(NPS관리활동_RAW!$G:$G="부정")))/SUMPRODUCT(--(NPS관리활동_RAW!A:A<=$BH$43)*(NPS관리활동_RAW!$D:$D=$B$51)*(NPS관리활동_RAW!$E:$E=TRIM($C52)))*100} -> #VALUE! | U52: =IFERROR(COUNTIFS(NPS관리활동_RAW!$D:$D, "영업점", NPS관리활동_RAW!$E:$E, TRIM(C52), NPS관리활동_RAW!$G:$G,"긍정")/COUNTIFS(NPS관리활동_RAW!$D:$D, "영업점", NPS관리활동_RAW!$E:$E, TRIM(C52))*100,0) -> 0 | AA52: =IFERROR(COUNTIFS(NPS관리활동_RAW!$D:$D, "영업점", NPS관리활동_RAW!$E:$E, TRIM(C52), NPS관리활동_RAW!$G:$G,"부정")/COUNTIFS(NPS관리활동_RAW!$D:$D, "영업점", NPS관리활동_RAW!$E:$E, TRIM(C52))*100,0) -> 0 | AG52: =AY52 -> 0 | AM52: {=AG52-(SUMPRODUCT(--(NPS관리활동_RAW!A:A<=$BH$43)*(NPS관리활동_RAW!$D:$D=$B$51)*(NPS관리활동_RAW!$E:$E=TRIM($C52))*(NPS관리활동_RAW!$H:$H="불만"))/SUMPRODUCT(--(NPS관리활동_RAW!A:A<=$BH$43)*(NPS관리활동_RAW!$D:$D=$B$51)*(NPS관리활동_RAW!$E:$E=TRIM($C52)))*100)} -> #VALUE! | AS52: =IFERROR(COUNTIFS(NPS관리활동_RAW!$D:$D, "영업점", NPS관리활동_RAW!$E:$E, TRIM($C52), NPS관리활동_RAW!$H:$H,"칭찬")/COUNTIFS(NPS관리활동_RAW!$D:$D, "영업점", NPS관리활동_RAW!$E:$E, TRIM($C52))*100,0) -> 0 | AY52: =IFERROR(COUNTIFS(NPS관리활동_RAW!$D:$D, "영업점", NPS관리활동_RAW!$E:$E, TRIM($C52), NPS관리활동_RAW!$H:$H,"불만")/COUNTIFS(NPS관리활동_RAW!$D:$D, "영업점", NPS관리활동_RAW!$E:$E, TRIM($C52))*100,0) -> 0
C53: 대기 | I53: =U53-AA53 -> 0 | O53: {=I53-(SUMPRODUCT(--(NPS관리활동_RAW!A:A<=$BH$43)*(NPS관리활동_RAW!$D:$D=$B$51)*(NPS관리활동_RAW!$E:$E=TRIM($C53))*(NPS관리활동_RAW!$G:$G="긍정"))-SUMPRODUCT(--(NPS관리활동_RAW!A:A<=$BH$43)*(NPS관리활동_RAW!$D:$D=$B$51)*(NPS관리활동_RAW!$E:$E=TRIM($C53))*(NPS관리활동_RAW!$G:$G="부정")))/SUMPRODUCT(--(NPS관리활동_RAW!A:A<=$BH$43)*(NPS관리활동_RAW!$D:$D=$B$51)*(NPS관리활동_RAW!$E:$E=TRIM($C53)))*100} -> #VALUE! | U53: =IFERROR(COUNTIFS(NPS관리활동_RAW!$D:$D, "영업점", NPS관리활동_RAW!$E:$E, TRIM(C53), NPS관리활동_RAW!$G:$G,"긍정")/COUNTIFS(NPS관리활동_RAW!$D:$D, "영업점", NPS관리활동_RAW!$E:$E, TRIM(C53))*100,0) -> 0 | AA53: =IFERROR(COUNTIFS(NPS관리활동_RAW!$D:$D, "영업점", NPS관리활동_RAW!$E:$E, TRIM(C53), NPS관리활동_RAW!$G:$G,"부정")/COUNTIFS(NPS관리활동_RAW!$D:$D, "영업점", NPS관리활동_RAW!$E:$E, TRIM(C53))*100,0) -> 0 | AG53: =AY53 -> 0 | AM53: {=AG53-(SUMPRODUCT(--(NPS관리활동_RAW!A:A<=$BH$43)*(NPS관리활동_RAW!$D:$D=$B$51)*(NPS관리활동_RAW!$E:$E=TRIM($C53))*(NPS관리활동_RAW!$H:$H="불만"))/SUMPRODUCT(--(NPS관리활동_RAW!A:A<=$BH$43)*(NPS관리활동_RAW!$D:$D=$B$51)*(NPS관리활동_RAW!$E:$E=TRIM($C53)))*100)} -> #VALUE! | AS53: =IFERROR(COUNTIFS(NPS관리활동_RAW!$D:$D, "영업점", NPS관리활동_RAW!$E:$E, TRIM($C53), NPS관리활동_RAW!$H:$H,"칭찬")/COUNTIFS(NPS관리활동_RAW!$D:$D, "영업점", NPS관리활동_RAW!$E:$E, TRIM($C53))*100,0) -> 0 | AY53: =IFERROR(COUNTIFS(NPS관리활동_RAW!$D:$D, "영업점", NPS관리활동_RAW!$E:$E, TRIM($C53), NPS관리활동_RAW!$H:$H,"불만")/COUNTIFS(NPS관리활동_RAW!$D:$D, "영업점", NPS관리활동_RAW!$E:$E, TRIM($C53))*100,0) -> 0
C54: 맞이/의도파악 | I54: =U54-AA54 -> 0 | O54: {=I54-(SUMPRODUCT(--(NPS관리활동_RAW!A:A<=$BH$43)*(NPS관리활동_RAW!$D:$D=$B$51)*(NPS관리활동_RAW!$E:$E=TRIM($C54))*(NPS관리활동_RAW!$G:$G="긍정"))-SUMPRODUCT(--(NPS관리활동_RAW!A:A<=$BH$43)*(NPS관리활동_RAW!$D:$D=$B$51)*(NPS관리활동_RAW!$E:$E=TRIM($C54))*(NPS관리활동_RAW!$G:$G="부정")))/SUMPRODUCT(--(NPS관리활동_RAW!A:A<=$BH$43)*(NPS관리활동_RAW!$D:$D=$B$51)*(NPS관리활동_RAW!$E:$E=TRIM($C54)))*100} -> #VALUE! | U54: =IFERROR(COUNTIFS(NPS관리활동_RAW!$D:$D, "영업점", NPS관리활동_RAW!$E:$E, TRIM(C54), NPS관리활동_RAW!$G:$G,"긍정")/COUNTIFS(NPS관리활동_RAW!$D:$D, "영업점", NPS관리활동_RAW!$E:$E, TRIM(C54))*100,0) -> 0 | AA54: =IFERROR(COUNTIFS(NPS관리활동_RAW!$D:$D, "영업점", NPS관리활동_RAW!$E:$E, TRIM(C54), NPS관리활동_RAW!$G:$G,"부정")/COUNTIFS(NPS관리활동_RAW!$D:$D, "영업점", NPS관리활동_RAW!$E:$E, TRIM(C54))*100,0) -> 0 | AG54: =AY54 -> 0 | AM54: {=AG54-(SUMPRODUCT(--(NPS관리활동_RAW!A:A<=$BH$43)*(NPS관리활동_RAW!$D:$D=$B$51)*(NPS관리활동_RAW!$E:$E=TRIM($C54))*(NPS관리활동_RAW!$H:$H="불만"))/SUMPRODUCT(--(NPS관리활동_RAW!A:A<=$BH$43)*(NPS관리활동_RAW!$D:$D=$B$51)*(NPS관리활동_RAW!$E:$E=TRIM($C54)))*100)} -> #VALUE! | AS54: =IFERROR(COUNTIFS(NPS관리활동_RAW!$D:$D, "영업점", NPS관리활동_RAW!$E:$E, TRIM($C54), NPS관리활동_RAW!$H:$H,"칭찬")/COUNTIFS(NPS관리활동_RAW!$D:$D, "영업점", NPS관리활동_RAW!$E:$E, TRIM($C54))*100,0) -> 0 | AY54: =IFERROR(COUNTIFS(NPS관리활동_RAW!$D:$D, "영업점", NPS관리활동_RAW!$E:$E, TRIM($C54), NPS관리활동_RAW!$H:$H,"불만")/COUNTIFS(NPS관리활동_RAW!$D:$D, "영업점", NPS관리활동_RAW!$E:$E, TRIM($C54))*100,0) -> 0
C55: 상담 | I55: =U55-AA55 -> 0 | O55: {=I55-(SUMPRODUCT(--(NPS관리활동_RAW!A:A<=$BH$43)*(NPS관리활동_RAW!$D:$D=$B$51)*(NPS관리활동_RAW!$E:$E=TRIM("직원상담"))*(NPS관리활동_RAW!$G:$G="긍정"))-SUMPRODUCT(--(NPS관리활동_RAW!A:A<=$BH$43)*(NPS관리활동_RAW!$D:$D=$B$51)*(NPS관리활동_RAW!$E:$E=TRIM("직원상담"))*(NPS관리활동_RAW!$G:$G="부정")))/SUMPRODUCT(--(NPS관리활동_RAW!A:A<=$BH$43)*(NPS관리활동_RAW!$D:$D=$B$51)*(NPS관리활동_RAW!$E:$E=TRIM("직원상담")))*100} -> #VALUE! | U55: =IFERROR(COUNTIFS(NPS관리활동_RAW!$D:$D, "영업점", NPS관리활동_RAW!$E:$E, TRIM("직원상담"), NPS관리활동_RAW!$G:$G,"긍정")/COUNTIFS(NPS관리활동_RAW!$D:$D, "영업점", NPS관리활동_RAW!$E:$E, TRIM("직원상담"))*100,0) -> 0 | AA55: =IFERROR(COUNTIFS(NPS관리활동_RAW!$D:$D, "영업점", NPS관리활동_RAW!$E:$E, TRIM("직원상담"), NPS관리활동_RAW!$G:$G,"부정")/COUNTIFS(NPS관리활동_RAW!$D:$D, "영업점", NPS관리활동_RAW!$E:$E, TRIM("직원상담"))*100,0) -> 0 | AG55: =AY55 -> 0 | AM55: {=AG55-(SUMPRODUCT(--(NPS관리활동_RAW!A:A<=$BH$43)*(NPS관리활동_RAW!$D:$D=$B$51)*(NPS관리활동_RAW!$E:$E="직원상담")*(NPS관리활동_RAW!$H:$H="불만"))/SUMPRODUCT(--(NPS관리활동_RAW!A:A<=$BH$43)*(NPS관리활동_RAW!$D:$D=$B$51)*(NPS관리활동_RAW!$E:$E="직원상담"))*100)} -> #VALUE! | AS55: =IFERROR(COUNTIFS(NPS관리활동_RAW!$D:$D, "영업점", NPS관리활동_RAW!$E:$E, "직원상담", NPS관리활동_RAW!$H:$H,"칭찬")/COUNTIFS(NPS관리활동_RAW!$D:$D, "영업점", NPS관리활동_RAW!$E:$E, "직원상담")*100,0) -> 0 | AY55: =IFERROR(COUNTIFS(NPS관리활동_RAW!$D:$D, "영업점", NPS관리활동_RAW!$E:$E, "직원상담", NPS관리활동_RAW!$H:$H,"불만")/COUNTIFS(NPS관리활동_RAW!$D:$D, "영업점", NPS관리활동_RAW!$E:$E, "직원상담")*100,0) -> 0
C56: 업무처리/배웅 | I56: =U56-AA56 -> 0 | O56: {=I56-(SUMPRODUCT(--(NPS관리활동_RAW!A:A<=$BH$43)*(NPS관리활동_RAW!$D:$D=$B$51)*(NPS관리활동_RAW!$E:$E=TRIM($C56))*(NPS관리활동_RAW!$G:$G="긍정"))-SUMPRODUCT(--(NPS관리활동_RAW!A:A<=$BH$43)*(NPS관리활동_RAW!$D:$D=$B$51)*(NPS관리활동_RAW!$E:$E=TRIM($C56))*(NPS관리활동_RAW!$G:$G="부정")))/SUMPRODUCT(--(NPS관리활동_RAW!A:A<=$BH$43)*(NPS관리활동_RAW!$D:$D=$B$51)*(NPS관리활동_RAW!$E:$E=TRIM($C56)))*100} -> #VALUE! | U56: =IFERROR(COUNTIFS(NPS관리활동_RAW!$D:$D, "영업점", NPS관리활동_RAW!$E:$E, TRIM(C56), NPS관리활동_RAW!$G:$G,"긍정")/COUNTIFS(NPS관리활동_RAW!$D:$D, "영업점", NPS관리활동_RAW!$E:$E, TRIM(C56))*100,0) -> 0 | AA56: =IFERROR(COUNTIFS(NPS관리활동_RAW!$D:$D, "영업점", NPS관리활동_RAW!$E:$E, TRIM(C56), NPS관리활동_RAW!$G:$G,"부정")/COUNTIFS(NPS관리활동_RAW!$D:$D, "영업점", NPS관리활동_RAW!$E:$E, TRIM(C56))*100,0) -> 0 | AG56: =AY56 -> 0 | AM56: {=AG56-(SUMPRODUCT(--(NPS관리활동_RAW!A:A<=$BH$43)*(NPS관리활동_RAW!$D:$D=$B$51)*(NPS관리활동_RAW!$E:$E=TRIM($C56))*(NPS관리활동_RAW!$H:$H="불만"))/SUMPRODUCT(--(NPS관리활동_RAW!A:A<=$BH$43)*(NPS관리활동_RAW!$D:$D=$B$51)*(NPS관리활동_RAW!$E:$E=TRIM($C56)))*100)} -> #VALUE! | AS56: =IFERROR(COUNTIFS(NPS관리활동_RAW!$D:$D, "영업점", NPS관리활동_RAW!$E:$E, TRIM($C56), NPS관리활동_RAW!$H:$H,"칭찬")/COUNTIFS(NPS관리활동_RAW!$D:$D, "영업점", NPS관리활동_RAW!$E:$E, TRIM($C56))*100,0) -> 0 | AY56: =IFERROR(COUNTIFS(NPS관리활동_RAW!$D:$D, "영업점", NPS관리활동_RAW!$E:$E, TRIM($C56), NPS관리활동_RAW!$H:$H,"불만")/COUNTIFS(NPS관리활동_RAW!$D:$D, "영업점", NPS관리활동_RAW!$E:$E, TRIM($C56))*100,0) -> 0
B57: 고객센터 | I57: =U57-AA57 -> #DIV/0! | O57: {=AK12-(SUMPRODUCT(--(NPS관리활동_RAW!A:A<=$BH$43)*(NPS관리활동_RAW!$D:$D="고객센터")*(NPS관리활동_RAW!$G:$G="긍정"))-SUMPRODUCT(--(NPS관리활동_RAW!A:A<=$BH$43)*(NPS관리활동_RAW!$D:$D="고객센터")*(NPS관리활동_RAW!$G:$G="부정")))/SUMPRODUCT(--(NPS관리활동_RAW!A:A<=$BH$43)*(NPS관리활동_RAW!$D:$D="고객센터"))*100} -> #DIV/0! | U57: =IFERROR(COUNTIFS(NPS관리활동_RAW!$D:$D, TRIM(B57), NPS관리활동_RAW!$G:$G, "*긍정*"),0)/IFERROR(COUNTIFS(NPS관리활동_RAW!$D:$D, TRIM(B57)), 1) * 100 -> #DIV/0! | AA57: =IFERROR(COUNTIFS(NPS관리활동_RAW!$D:$D, TRIM(B57), NPS관리활동_RAW!$G:$G, "*부정*"),0)/IFERROR(COUNTIFS(NPS관리활동_RAW!$D:$D, TRIM(B57)), 1) * 100 -> #DIV/0! | AG57: =AY57 -> #DIV/0! | AM57: {=AG57-(SUMPRODUCT(--(NPS관리활동_RAW!A:A<=$BH$43)*(NPS관리활동_RAW!$D:$D="고객센터")*(NPS관리활동_RAW!$H:$H="불만"))/SUMPRODUCT(--(NPS관리활동_RAW!A:A<=$BH$43)*(NPS관리활동_RAW!$D:$D="고객센터"))*100)} -> #DIV/0! | AS57: =IFERROR(COUNTIFS(NPS관리활동_RAW!$D:$D, TRIM(B57), NPS관리활동_RAW!$H:$H, "*칭찬*"),0)/IFERROR(COUNTIFS(NPS관리활동_RAW!$D:$D, TRIM(B57)), 1) * 100 -> #DIV/0! | AY57: =IFERROR(COUNTIFS(NPS관리활동_RAW!$D:$D, TRIM(B57), NPS관리활동_RAW!$H:$H, "*불만*"),0)/IFERROR(COUNTIFS(NPS관리활동_RAW!$D:$D, TRIM(B57)), 1) * 100 -> #DIV/0!
C58: 버튼식ARS | I58: =U58-AA58 -> 0 | O58: {=I58-(SUMPRODUCT(--(NPS관리활동_RAW!A:A<=$BH$43)*(NPS관리활동_RAW!$D:$D=$B$57)*(NPS관리활동_RAW!$E:$E=TRIM($C58))*(NPS관리활동_RAW!$G:$G="긍정"))-SUMPRODUCT(--(NPS관리활동_RAW!A:A<=$BH$43)*(NPS관리활동_RAW!$D:$D=$B$57)*(NPS관리활동_RAW!$E:$E=TRIM($C58))*(NPS관리활동_RAW!$G:$G="부정")))/SUMPRODUCT(--(NPS관리활동_RAW!A:A<=$BH$43)*(NPS관리활동_RAW!$D:$D=$B$57)*(NPS관리활동_RAW!$E:$E=TRIM($C58)))*100} -> #VALUE! | U58: =IFERROR(COUNTIFS(NPS관리활동_RAW!$D:$D, "고객센터", NPS관리활동_RAW!$E:$E, TRIM(C58), NPS관리활동_RAW!$G:$G,"긍정")/COUNTIFS(NPS관리활동_RAW!$D:$D, "고객센터", NPS관리활동_RAW!$E:$E, TRIM(C58))*100,0) -> 0 | AA58: =IFERROR(COUNTIFS(NPS관리활동_RAW!$D:$D, "고객센터", NPS관리활동_RAW!$E:$E, TRIM(C58), NPS관리활동_RAW!$G:$G,"부정")/COUNTIFS(NPS관리활동_RAW!$D:$D, "고객센터", NPS관리활동_RAW!$E:$E, TRIM(C58))*100,0) -> 0 | AG58: =AY58 -> 0 | AM58: {=AG58-(SUMPRODUCT(--(NPS관리활동_RAW!A:A<=$BH$43)*(NPS관리활동_RAW!$D:$D=$B$57)*(NPS관리활동_RAW!$E:$E=TRIM($C58))*(NPS관리활동_RAW!$H:$H="불만"))/SUMPRODUCT(--(NPS관리활동_RAW!A:A<=$BH$43)*(NPS관리활동_RAW!$D:$D=$B$57)*(NPS관리활동_RAW!$E:$E=TRIM($C58)))*100)} -> #VALUE! | AS58: =IFERROR(COUNTIFS(NPS관리활동_RAW!$D:$D, "고객센터", NPS관리활동_RAW!$E:$E, TRIM($C58), NPS관리활동_RAW!$H:$H,"칭찬")/COUNTIFS(NPS관리활동_RAW!$D:$D, "고객센터", NPS관리활동_RAW!$E:$E, TRIM($C58))*100,0) -> 0 | AY58: =IFERROR(COUNTIFS(NPS관리활동_RAW!$D:$D, "고객센터", NPS관리활동_RAW!$E:$E, TRIM($C58), NPS관리활동_RAW!$H:$H,"불만")/COUNTIFS(NPS관리활동_RAW!$D:$D, "고객센터", NPS관리활동_RAW!$E:$E, TRIM($C58))*100,0) -> 0
C59: 보이는ARS | I59: =U59-AA59 -> 0 | O59: {=I59-(SUMPRODUCT(--(NPS관리활동_RAW!A:A<=$BH$43)*(NPS관리활동_RAW!$D:$D=$B$57)*(NPS관리활동_RAW!$E:$E=TRIM($C59))*(NPS관리활동_RAW!$G:$G="긍정"))-SUMPRODUCT(--(NPS관리활동_RAW!A:A<=$BH$43)*(NPS관리활동_RAW!$D:$D=$B$57)*(NPS관리활동_RAW!$E:$E=TRIM($C59))*(NPS관리활동_RAW!$G:$G="부정")))/SUMPRODUCT(--(NPS관리활동_RAW!A:A<=$BH$43)*(NPS관리활동_RAW!$D:$D=$B$57)*(NPS관리활동_RAW!$E:$E=TRIM($C59)))*100} -> #VALUE! | U59: =IFERROR(COUNTIFS(NPS관리활동_RAW!$D:$D, "고객센터", NPS관리활동_RAW!$E:$E, TRIM(C59), NPS관리활동_RAW!$G:$G,"긍정")/COUNTIFS(NPS관리활동_RAW!$D:$D, "고객센터", NPS관리활동_RAW!$E:$E, TRIM(C59))*100,0) -> 0 | AA59: =IFERROR(COUNTIFS(NPS관리활동_RAW!$D:$D, "고객센터", NPS관리활동_RAW!$E:$E, TRIM(C59), NPS관리활동_RAW!$G:$G,"부정")/COUNTIFS(NPS관리활동_RAW!$D:$D, "고객센터", NPS관리활동_RAW!$E:$E, TRIM(C59))*100,0) -> 0 | AG59: =AY59 -> 0 | AM59: {=AG59-(SUMPRODUCT(--(NPS관리활동_RAW!A:A<=$BH$43)*(NPS관리활동_RAW!$D:$D=$B$57)*(NPS관리활동_RAW!$E:$E=TRIM($C59))*(NPS관리활동_RAW!$H:$H="불만"))/SUMPRODUCT(--(NPS관리활동_RAW!A:A<=$BH$43)*(NPS관리활동_RAW!$D:$D=$B$57)*(NPS관리활동_RAW!$E:$E=TRIM($C59)))*100)} -> #VALUE! | AS59: =IFERROR(COUNTIFS(NPS관리활동_RAW!$D:$D, "고객센터", NPS관리활동_RAW!$E:$E, TRIM($C59), NPS관리활동_RAW!$H:$H,"칭찬")/COUNTIFS(NPS관리활동_RAW!$D:$D, "고객센터", NPS관리활동_RAW!$E:$E, TRIM($C59))*100,0) -> 0 | AY59: =IFERROR(COUNTIFS(NPS관리활동_RAW!$D:$D, "고객센터", NPS관리활동_RAW!$E:$E, TRIM($C59), NPS관리활동_RAW!$H:$H,"불만")/COUNTIFS(NPS관리활동_RAW!$D:$D, "고객센터", NPS관리활동_RAW!$E:$E, TRIM($C59))*100,0) -> 0
C60: 대기 | I60: =U60-AA60 -> 0 | O60: {=I60-(SUMPRODUCT(--(NPS관리활동_RAW!A:A<=$BH$43)*(NPS관리활동_RAW!$D:$D=$B$57)*(NPS관리활동_RAW!$E:$E=TRIM($C60))*(NPS관리활동_RAW!$G:$G="긍정"))-SUMPRODUCT(--(NPS관리활동_RAW!A:A<=$BH$43)*(NPS관리활동_RAW!$D:$D=$B$57)*(NPS관리활동_RAW!$E:$E=TRIM($C60))*(NPS관리활동_RAW!$G:$G="부정")))/SUMPRODUCT(--(NPS관리활동_RAW!A:A<=$BH$43)*(NPS관리활동_RAW!$D:$D=$B$57)*(NPS관리활동_RAW!$E:$E=TRIM($C60)))*100} -> #VALUE! | U60: =IFERROR(COUNTIFS(NPS관리활동_RAW!$D:$D, "고객센터", NPS관리활동_RAW!$E:$E, TRIM(C60), NPS관리활동_RAW!$G:$G,"긍정")/COUNTIFS(NPS관리활동_RAW!$D:$D, "고객센터", NPS관리활동_RAW!$E:$E, TRIM(C60))*100,0) -> 0 | AA60: =IFERROR(COUNTIFS(NPS관리활동_RAW!$D:$D, "고객센터", NPS관리활동_RAW!$E:$E, TRIM(C60), NPS관리활동_RAW!$G:$G,"부정")/COUNTIFS(NPS관리활동_RAW!$D:$D, "고객센터", NPS관리활동_RAW!$E:$E, TRIM(C60))*100,0) -> 0 | AG60: =AY60 -> 0 | AM60: {=AG60-(SUMPRODUCT(--(NPS관리활동_RAW!A:A<=$BH$43)*(NPS관리활동_RAW!$D:$D=$B$57)*(NPS관리활동_RAW!$E:$E=TRIM($C60))*(NPS관리활동_RAW!$H:$H="불만"))/SUMPRODUCT(--(NPS관리활동_RAW!A:A<=$BH$43)*(NPS관리활동_RAW!$D:$D=$B$57)*(NPS관리활동_RAW!$E:$E=TRIM($C60)))*100)} -> #VALUE! | AS60: =IFERROR(COUNTIFS(NPS관리활동_RAW!$D:$D, "고객센터", NPS관리활동_RAW!$E:$E, TRIM($C60), NPS관리활동_RAW!$H:$H,"칭찬")/COUNTIFS(NPS관리활동_RAW!$D:$D, "고객센터", NPS관리활동_RAW!$E:$E, TRIM($C60))*100,0) -> 0 | AY60: =IFERROR(COUNTIFS(NPS관리활동_RAW!$D:$D, "고객센터", NPS관리활동_RAW!$E:$E, TRIM($C60), NPS관리활동_RAW!$H:$H,"불만")/COUNTIFS(NPS관리활동_RAW!$D:$D, "고객센터", NPS관리활동_RAW!$E:$E, TRIM($C60))*100,0) -> 0
C61: 챗봇상담 | I61: =U61-AA61 -> 0 | O61: {=I61-(SUMPRODUCT(--(NPS관리활동_RAW!A:A<=$BH$43)*(NPS관리활동_RAW!$D:$D=$B$57)*(NPS관리활동_RAW!$E:$E=TRIM($C61))*(NPS관리활동_RAW!$G:$G="긍정"))-SUMPRODUCT(--(NPS관리활동_RAW!A:A<=$BH$43)*(NPS관리활동_RAW!$D:$D=$B$57)*(NPS관리활동_RAW!$E:$E=TRIM($C61))*(NPS관리활동_RAW!$G:$G="부정")))/SUMPRODUCT(--(NPS관리활동_RAW!A:A<=$BH$43)*(NPS관리활동_RAW!$D:$D=$B$57)*(NPS관리활동_RAW!$E:$E=TRIM($C61)))*100} -> #VALUE! | U61: =IFERROR(COUNTIFS(NPS관리활동_RAW!$D:$D, "고객센터", NPS관리활동_RAW!$E:$E, TRIM(C61), NPS관리활동_RAW!$G:$G,"긍정")/COUNTIFS(NPS관리활동_RAW!$D:$D, "고객센터", NPS관리활동_RAW!$E:$E, TRIM(C61))*100,0) -> 0 | AA61: =IFERROR(COUNTIFS(NPS관리활동_RAW!$D:$D, "고객센터", NPS관리활동_RAW!$E:$E, TRIM(C61), NPS관리활동_RAW!$G:$G,"부정")/COUNTIFS(NPS관리활동_RAW!$D:$D, "고객센터", NPS관리활동_RAW!$E:$E, TRIM(C61))*100,0) -> 0 | AG61: =AY61 -> 0 | AM61: {=AG61-(SUMPRODUCT(--(NPS관리활동_RAW!A:A<=$BH$43)*(NPS관리활동_RAW!$D:$D=$B$57)*(NPS관리활동_RAW!$E:$E=TRIM($C61))*(NPS관리활동_RAW!$H:$H="불만"))/SUMPRODUCT(--(NPS관리활동_RAW!A:A<=$BH$43)*(NPS관리활동_RAW!$D:$D=$B$57)*(NPS관리활동_RAW!$E:$E=TRIM($C61)))*100)} -> #VALUE! | AS61: =IFERROR(COUNTIFS(NPS관리활동_RAW!$D:$D, "고객센터", NPS관리활동_RAW!$E:$E, TRIM($C61), NPS관리활동_RAW!$H:$H,"칭찬")/COUNTIFS(NPS관리활동_RAW!$D:$D, "고객센터", NPS관리활동_RAW!$E:$E, TRIM($C61))*100,0) -> 0 | AY61: =IFERROR(COUNTIFS(NPS관리활동_RAW!$D:$D, "고객센터", NPS관리활동_RAW!$E:$E, TRIM($C61), NPS관리활동_RAW!$H:$H,"불만")/COUNTIFS(NPS관리활동_RAW!$D:$D, "고객센터", NPS관리활동_RAW!$E:$E, TRIM($C61))*100,0) -> 0
...

Sheet 3.VOC대시보드
B2: | VOC 대시보드 | BD2: {{cm_yyyymmdd}}
B4: ■ 채널별 불만 VOC 요약 및 지난주 비교
B7: 채널 | I7: 지난주 VOC와 비교
J8: 불만사항 요약
L9: 불만 VOC 예시
B10: 스타뱅킹 | I10: {{S3_compare_1}}
J11: {{S3_complaint1_1}}
L12: 예시) {{S3_complaint1_2}}
L13: 예시) {{S3_complaint1_3}}
L14: 예시) {{S3_complaint1_4}}
J15: {{S3_complaint2_1}}
L16: 예시) {{S3_complaint2_2}}
L17: 예시) {{S3_complaint2_3}}
L18: 예시) {{S3_complaint2_4}}
J19: {{S3_complaint3_1}}
L20: 예시) {{S3_complaint3_2}}
L21: 예시) {{S3_complaint3_3}}
L22: 예시) {{S3_complaint3_4}}
B23: 영업점 | I23: {{S3_compare_2}}
B24: 영업점 | J24: {{S3_complaint1_5}}
L25: 예시) {{S3_complaint1_6}}
L26: 예시) {{S3_complaint1_7}}
L27: 예시) {{S3_complaint1_8}}
J28: {{S3_complaint2_5}}
L29: 예시) {{S3_complaint2_6}}
L30: 예시) {{S3_complaint2_7}}
L31: 예시) {{S3_complaint2_8}}
J32: {{S3_complaint3_5}}
L33: 예시) {{S3_complaint3_6}}
L34: 예시) {{S3_complaint3_7}}
L35: 예시) {{S3_complaint3_8}}
B36: 고객센터 | I36: {{S3_compare_3}}
B37: 고객센터 | J37: {{S3_complaint1_9}}
L38: 예시) {{S3_complaint1_10}}
L39: 예시) {{S3_complaint1_11}}
L40: 예시) {{S3_complaint1_12}}
J41: {{S3_complaint2_9}}
L42: 예시) {{S3_complaint2_10}}
L43: 예시) {{S3_complaint2_11}}
L44: 예시) {{S3_complaint2_12}}
...

Sheet BU_NPS_RAW

Sheet NPS관리활동_RAW

Sheet 고객경험단계별NPS_RAW
