Workbook

Sheet 1.NPS대시보드
B2: {{region_group_name}} 대면채널 NPS 주간 보고서(1/2)
B3: {{base_date}} 기준
B4: 1. NPS 현황 | BD4: ('{{start_date}}~'{{friday_b01w}} 응답 기준)
BG5: 지역영업그룹 | BH5: NPS | BI5: 전행NPS
C6: 순고객추천지수(NPS) | BG6: {{S1_지역영업그룹_1}} | BH6: {{S1_지역영업그룹NPS_1}} | BI6: {{S1_전행NPS_1}}
BG7: {{S1_지역영업그룹_2}} | BH7: {{S1_지역영업그룹NPS_2}} | BI7: {{S1_전행NPS_2}}
C8: 전월 대비 | H8: {{S1_NPS변동_1}} | K8: {{S1_NPS변동구분_1}} | BG8: {{S1_지역영업그룹_3}} | BH8: {{S1_지역영업그룹NPS_3}} | BI8: {{S1_전행NPS_3}}
BG9: {{S1_지역영업그룹_4}} | BH9: {{S1_지역영업그룹NPS_4}} | BI9: {{S1_전행NPS_4}}
BG10: {{S1_지역영업그룹_5}} | BH10: {{S1_지역영업그룹NPS_5}} | BI10: {{S1_전행NPS_5}}
C11: {{S1_전월NPS_1}} | J11: {{S1_금주NPS_1}}
C12: 전월 | M12: 이번주
C16: 월별 고객 충성도 그룹 및 NPS 추이
BG20: 기준월 | BH20: 추천비율 | BI20: 중립비율 | BJ20: 비추천비율 | BK20: NPS
BG21: 1월 | BH21: {{S1_추천비율_1}} | BI21: {{S1_중립비율_1}} | BJ21: {{S1_비추천비율_1}} | BK21: {{S1_NPS_1}}
BG22: 2월 | BH22: {{S1_추천비율_2}} | BI22: {{S1_중립비율_2}} | BJ22: {{S1_비추천비율_2}} | BK22: {{S1_NPS_2}}
BG23: 3월 | BH23: {{S1_추천비율_3}} | BI23: {{S1_중립비율_3}} | BJ23: {{S1_비추천비율_3}} | BK23: {{S1_NPS_3}}
BG24: 4월 | BH24: {{S1_추천비율_4}} | BI24: {{S1_중립비율_4}} | BJ24: {{S1_비추천비율_4}} | BK24: {{S1_NPS_4}}
BG25: 5월 | BH25: {{S1_추천비율_5}} | BI25: {{S1_중립비율_5}} | BJ25: {{S1_비추천비율_5}} | BK25: {{S1_NPS_5}}
BG26: 6월 | BH26: {{S1_추천비율_6}} | BI26: {{S1_중립비율_6}} | BJ26: {{S1_비추천비율_6}} | BK26: {{S1_NPS_6}}
BG27: 7월 | BH27: {{S1_추천비율_7}} | BI27: {{S1_중립비율_7}} | BJ27: {{S1_비추천비율_7}} | BK27: {{S1_NPS_7}}
B28: 2. {{region_group_name}} PG/RG별 NPS 현황 | BD28: ('{{start_date}}~'{{friday_b01w}} 응답 기준) | BG28: 8월 | BH28: {{S1_추천비율_8}} | BI28: {{S1_중립비율_8}} | BJ28: {{S1_비추천비율_8}} | BK28: {{S1_NPS_8}}
BG29: 9월 | BH29: {{S1_추천비율_9}} | BI29: {{S1_중립비율_9}} | BJ29: {{S1_비추천비율_9}} | BK29: {{S1_NPS_9}}
C30: PG/RG명 | K30: 누적 NPS | T30: 월별 NPS | BG30: 10월 | BH30: {{S1_추천비율_10}} | BI30: {{S1_중립비율_10}} | BJ30: {{S1_비추천비율_10}} | BK30: {{S1_NPS_10}}
K31: 전월 | N31: 당월 | Q31: 대비 | T31: 1월 | W31: 2월 | Z31: 3월 | AC31: 4월 | AF31: 5월 | AI31: 6월 | AL31: 7월 | AO31: 8월 | AR31: 9월 | AU31: 10월 | AX31: 11월 | BA31: 12월 | BG31: 11월 | BH31: {{S1_추천비율_11}} | BI31: {{S1_중립비율_11}} | BJ31: {{S1_비추천비율_11}} | BK31: {{S1_NPS_11}}
C32: {{S1_지역본부_1}} | BG32: 12월 | BH32: {{S1_추천비율_12}} | BI32: {{S1_중립비율_12}} | BJ32: {{S1_비추천비율_12}} | BK32: {{S1_NPS_12}}
J33: 영업점 | K33: {{S1_전월PGNPS_1}} | N33: {{S1_당월PGNPS_1}} | Q33: {{S1_PGNPS변동_1}} | T33: {{S1_1월PGNPS_1}} | W33: {{S1_2월PGNPS_1}} | Z33: {{S1_3월PGNPS_1}} | AC33: {{S1_4월PGNPS_1}} | AF33: {{S1_5월PGNPS_1}} | AI33: {{S1_6월PGNPS_1}} | AL33: {{S1_7월PGNPS_1}} | AO33: {{S1_8월PGNPS_1}} | AR33: {{S1_9월PGNPS_1}} | AU33: {{S1_10월PGNPS_1}} | AX33: {{S1_11월PGNPS_1}} | BA33: {{S1_12월PGNPS_1}}
J34: 직원 | K34: {{S1_전월PGNPS_2}} | N34: {{S1_당월PGNPS_2}} | Q34: {{S1_PGNPS변동_2}} | T34: {{S1_1월PGNPS_2}} | W34: {{S1_2월PGNPS_2}} | Z34: {{S1_3월PGNPS_2}} | AC34: {{S1_4월PGNPS_2}} | AF34: {{S1_5월PGNPS_2}} | AI34: {{S1_6월PGNPS_2}} | AL34: {{S1_7월PGNPS_2}} | AO34: {{S1_8월PGNPS_2}} | AR34: {{S1_9월PGNPS_2}} | AU34: {{S1_10월PGNPS_2}} | AX34: {{S1_11월PGNPS_2}} | BA34: {{S1_12월PGNPS_2}}
C35: {{S1_지역본부_3}}
J36: 영업점 | K36: {{S1_전월PGNPS_3}} | N36: {{S1_당월PGNPS_3}} | Q36: {{S1_PGNPS변동_3}} | T36: {{S1_1월PGNPS_3}} | W36: {{S1_2월PGNPS_3}} | Z36: {{S1_3월PGNPS_3}} | AC36: {{S1_4월PGNPS_3}} | AF36: {{S1_5월PGNPS_3}} | AI36: {{S1_6월PGNPS_3}} | AL36: {{S1_7월PGNPS_3}} | AO36: {{S1_8월PGNPS_3}} | AR36: {{S1_9월PGNPS_3}} | AU36: {{S1_10월PGNPS_3}} | AX36: {{S1_11월PGNPS_3}} | BA36: {{S1_12월PGNPS_3}}
J37: 직원 | K37: {{S1_전월PGNPS_4}} | N37: {{S1_당월PGNPS_4}} | Q37: {{S1_PGNPS변동_4}} | T37: {{S1_1월PGNPS_4}} | W37: {{S1_2월PGNPS_4}} | Z37: {{S1_3월PGNPS_4}} | AC37: {{S1_4월PGNPS_4}} | AF37: {{S1_5월PGNPS_4}} | AI37: {{S1_6월PGNPS_4}} | AL37: {{S1_7월PGNPS_4}} | AO37: {{S1_8월PGNPS_4}} | AR37: {{S1_9월PGNPS_4}} | AU37: {{S1_10월PGNPS_4}} | AX37: {{S1_11월PGNPS_4}} | BA37: {{S1_12월PGNPS_4}}
C38: {{S1_지역본부_5}}
J39: 영업점 | K39: {{S1_전월PGNPS_5}} | N39: {{S1_당월PGNPS_5}} | Q39: {{S1_PGNPS변동_5}} | T39: {{S1_1월PGNPS_5}} | W39: {{S1_2월PGNPS_5}} | Z39: {{S1_3월PGNPS_5}} | AC39: {{S1_4월PGNPS_5}} | AF39: {{S1_5월PGNPS_5}} | AI39: {{S1_6월PGNPS_5}} | AL39: {{S1_7월PGNPS_5}} | AO39: {{S1_8월PGNPS_5}} | AR39: {{S1_9월PGNPS_5}} | AU39: {{S1_10월PGNPS_5}} | AX39: {{S1_11월PGNPS_5}} | BA39: {{S1_12월PGNPS_5}}
J40: 직원 | K40: {{S1_전월PGNPS_6}} | N40: {{S1_당월PGNPS_6}} | Q40: {{S1_PGNPS변동_6}} | T40: {{S1_1월PGNPS_6}} | W40: {{S1_2월PGNPS_6}} | Z40: {{S1_3월PGNPS_6}} | AC40: {{S1_4월PGNPS_6}} | AF40: {{S1_5월PGNPS_6}} | AI40: {{S1_6월PGNPS_6}} | AL40: {{S1_7월PGNPS_6}} | AO40: {{S1_8월PGNPS_6}} | AR40: {{S1_9월PGNPS_6}} | AU40: {{S1_10월PGNPS_6}} | AX40: {{S1_11월PGNPS_6}} | BA40: {{S1_12월PGNPS_6}}
C41: {{S1_지역본부_7}}
J42: 영업점 | K42: {{S1_전월PGNPS_7}} | N42: {{S1_당월PGNPS_7}} | Q42: {{S1_PGNPS변동_7}} | T42: {{S1_1월PGNPS_7}} | W42: {{S1_2월PGNPS_7}} | Z42: {{S1_3월PGNPS_7}} | AC42: {{S1_4월PGNPS_7}} | AF42: {{S1_5월PGNPS_7}} | AI42: {{S1_6월PGNPS_7}} | AL42: {{S1_7월PGNPS_7}} | AO42: {{S1_8월PGNPS_7}} | AR42: {{S1_9월PGNPS_7}} | AU42: {{S1_10월PGNPS_7}} | AX42: {{S1_11월PGNPS_7}} | BA42: {{S1_12월PGNPS_7}}
J43: 직원 | K43: {{S1_전월PGNPS_8}} | N43: {{S1_당월PGNPS_8}} | Q43: {{S1_PGNPS변동_8}} | T43: {{S1_1월PGNPS_8}} | W43: {{S1_2월PGNPS_8}} | Z43: {{S1_3월PGNPS_8}} | AC43: {{S1_4월PGNPS_8}} | AF43: {{S1_5월PGNPS_8}} | AI43: {{S1_6월PGNPS_8}} | AL43: {{S1_7월PGNPS_8}} | AO43: {{S1_8월PGNPS_8}} | AR43: {{S1_9월PGNPS_8}} | AU43: {{S1_10월PGNPS_8}} | AX43: {{S1_11월PGNPS_8}} | BA43: {{S1_12월PGNPS_8}}
C44: {{S1_지역본부_9}}
J45: 영업점 | K45: {{S1_전월PGNPS_9}} | N45: {{S1_당월PGNPS_9}} | Q45: {{S1_PGNPS변동_9}} | T45: {{S1_1월PGNPS_9}} | W45: {{S1_2월PGNPS_9}} | Z45: {{S1_3월PGNPS_9}} | AC45: {{S1_4월PGNPS_9}} | AF45: {{S1_5월PGNPS_9}} | AI45: {{S1_6월PGNPS_9}} | AL45: {{S1_7월PGNPS_9}} | AO45: {{S1_8월PGNPS_9}} | AR45: {{S1_9월PGNPS_9}} | AU45: {{S1_10월PGNPS_9}} | AX45: {{S1_11월PGNPS_9}} | BA45: {{S1_12월PGNPS_9}}
J46: 직원 | K46: {{S1_전월PGNPS_10}} | N46: {{S1_당월PGNPS_10}} | Q46: {{S1_PGNPS변동_10}} | T46: {{S1_1월PGNPS_10}} | W46: {{S1_2월PGNPS_10}} | Z46: {{S1_3월PGNPS_10}} | AC46: {{S1_4월PGNPS_10}} | AF46: {{S1_5월PGNPS_10}} | AI46: {{S1_6월PGNPS_10}} | AL46: {{S1_7월PGNPS_10}} | AO46: {{S1_8월PGNPS_10}} | AR46: {{S1_9월PGNPS_10}} | AU46: {{S1_10월PGNPS_10}} | AX46: {{S1_11월PGNPS_10}} | BA46: {{S1_12월PGNPS_10}}
C47: {{S1_지역본부_11}}
...

Sheet 2.VOC대시보드
B2: {{region_group_name}} 대면채널 NPS 주간 보고서(2/2)
B3: {{base_date}} 기준
B4: 3. 고객불만지수(Customer Complaint Index) | BD4: ('{{start_date}}~'{{friday_b01w}} 응답 기준)
C5: 고객경험 VOC 분석결과로, 고객불만지수가 높을수록 고객 불만의견이 많다는 의미입니다. | BG5: 지역영업그룹 | BH5: CCI | BI5: 전행CCI
C6: 고객불만지수(CCI) | BG6: 강남영업추진그룹 | BH6: =COUNTIFS('CCI raw'!$R:$R, "불만", 'CCI raw'!$H:$H, BG6) / COUNTIF('CCI raw'!$H:$H, BG6) * 100 -> #DIV/0! | BI6: =COUNTIFS('CCI raw'!$R:$R, "불만") / COUNTA('CCI raw'!$R:$R) * 100 -> #DIV/0!
BG7: 강북영업추진그룹 | BH7: =COUNTIFS('CCI raw'!$R:$R, "불만", 'CCI raw'!$H:$H, BG7) / COUNTIF('CCI raw'!$H:$H, BG7) * 100 -> #DIV/0! | BI7: =BI6 -> #DIV/0!
C8: 전월 대비 | H8: =J11-C11 -> #N/A | K8: =IF(H8>0, "상승", IF(H8=0, "동일", "감소")) -> #N/A | BG8: 수도권영업추진그룹 | BH8: =COUNTIFS('CCI raw'!$R:$R, "불만", 'CCI raw'!$H:$H, BG8) / COUNTIF('CCI raw'!$H:$H, BG8) * 100 -> #DIV/0! | BI8: =BI7 -> #DIV/0!
BG9: 영남영업추진그룹 | BH9: =COUNTIFS('CCI raw'!$R:$R, "불만", 'CCI raw'!$H:$H, BG9) / COUNTIF('CCI raw'!$H:$H, BG9) * 100 -> #DIV/0! | BI9: =BI8 -> #DIV/0!
BG10: 충청호남영업추진그룹 | BH10: =COUNTIFS('CCI raw'!$R:$R, "불만", 'CCI raw'!$H:$H, BG10) / COUNTIF('CCI raw'!$H:$H, BG10) * 100 -> #DIV/0! | BI10: =BI9 -> #DIV/0!
C11: {=SUMPRODUCT(--('CCI raw'!A:A <= '2.VOC대시보드'!BH14) * ('CCI raw'!$R:$R = "불만") * ('CCI raw'!$H:$H = LEFT(B2,8))) / SUMPRODUCT(--('CCI raw'!A:A <= '2.VOC대시보드'!BH14) * ('CCI raw'!$H:$H = LEFT(B2,8))) * 100} -> #VALUE! | J11: =_xlfn.XLOOKUP(LEFT(B2,8),BG6:BG10,BH6:BH10) -> #N/A
C12: 전월 | M12: 이번주
BG14: 전월 | BH14: {=TEXT(EOMONTH(DATE(LEFT(MAX(VALUE('CCI raw'!A2:A1000000)),4), MID(MAX(VALUE('CCI raw'!A2:A1000000)),5,2), RIGHT(MAX(VALUE('CCI raw'!A2:A1000000)),2)), -1), "yyyymmdd")} -> #VALUE!
C16: 월별 고객불만지수 추이
BG20: 기준월 | BH20: 칭찬비율 | BI20: 불만비율 | BJ20: CCI
BG21: 1월 | BH21: =COUNTIFS('CCI raw'!$R:$R, "칭찬", 'CCI raw'!$A:$A, "202601*") / COUNTIF('CCI raw'!$A:$A, "202601*") * 100 -> #DIV/0! | BI21: =COUNTIFS('CCI raw'!$R:$R, "불만", 'CCI raw'!$A:$A, "202601*") / COUNTIF('CCI raw'!$A:$A, "202601*") * 100 -> #DIV/0! | BJ21: =BI21 -> #DIV/0!
BG22: 2월 | BH22: =COUNTIFS('CCI raw'!$R:$R, "칭찬", 'CCI raw'!$A:$A, "202602*") / COUNTIF('CCI raw'!$A:$A, "202602*") * 100 -> #DIV/0! | BI22: =COUNTIFS('CCI raw'!$R:$R, "불만", 'CCI raw'!$A:$A, "202602*") / COUNTIF('CCI raw'!$A:$A, "202602*") * 100 -> #DIV/0! | BJ22: =BI22 -> #DIV/0!
BG23: 3월 | BH23: =COUNTIFS('CCI raw'!$R:$R, "칭찬", 'CCI raw'!$A:$A, "202603*") / COUNTIF('CCI raw'!$A:$A, "202603*") * 100 -> #DIV/0! | BI23: =COUNTIFS('CCI raw'!$R:$R, "불만", 'CCI raw'!$A:$A, "202603*") / COUNTIF('CCI raw'!$A:$A, "202603*") * 100 -> #DIV/0! | BJ23: =BI23 -> #DIV/0!
BG24: 4월 | BH24: =COUNTIFS('CCI raw'!$R:$R, "칭찬", 'CCI raw'!$A:$A, "202604*") / COUNTIF('CCI raw'!$A:$A, "202604*") * 100 -> #DIV/0! | BI24: =COUNTIFS('CCI raw'!$R:$R, "불만", 'CCI raw'!$A:$A, "202604*") / COUNTIF('CCI raw'!$A:$A, "202604*") * 100 -> #DIV/0! | BJ24: =BI24 -> #DIV/0!
BG25: 5월 | BH25: =COUNTIFS('CCI raw'!$R:$R, "칭찬", 'CCI raw'!$A:$A, "202605*") / COUNTIF('CCI raw'!$A:$A, "202605*") * 100 -> #DIV/0! | BI25: =COUNTIFS('CCI raw'!$R:$R, "불만", 'CCI raw'!$A:$A, "202605*") / COUNTIF('CCI raw'!$A:$A, "202605*") * 100 -> #DIV/0! | BJ25: =BI25 -> #DIV/0!
BG26: 6월 | BH26: =COUNTIFS('CCI raw'!$R:$R, "칭찬", 'CCI raw'!$A:$A, "202606*") / COUNTIF('CCI raw'!$A:$A, "202606*") * 100 -> #DIV/0! | BI26: =COUNTIFS('CCI raw'!$R:$R, "불만", 'CCI raw'!$A:$A, "202606*") / COUNTIF('CCI raw'!$A:$A, "202606*") * 100 -> #DIV/0! | BJ26: =BI26 -> #DIV/0!
BG27: 7월 | BH27: =COUNTIFS('CCI raw'!$R:$R, "칭찬", 'CCI raw'!$A:$A, "202607*") / COUNTIF('CCI raw'!$A:$A, "202607*") * 100 -> #DIV/0! | BI27: =COUNTIFS('CCI raw'!$R:$R, "불만", 'CCI raw'!$A:$A, "202607*") / COUNTIF('CCI raw'!$A:$A, "202607*") * 100 -> #DIV/0! | BJ27: =BI27 -> #DIV/0!
B28: 4. {{region_group_name}} 불만 VOC 요약 | BD28: ('{{monday_b02w}}~'{{friday_b01w}} 응답 기준) | BG28: 8월 | BH28: =COUNTIFS('CCI raw'!$R:$R, "칭찬", 'CCI raw'!$A:$A, "202608*") / COUNTIF('CCI raw'!$A:$A, "202608*") * 100 -> #DIV/0! | BI28: =COUNTIFS('CCI raw'!$R:$R, "불만", 'CCI raw'!$A:$A, "202608*") / COUNTIF('CCI raw'!$A:$A, "202608*") * 100 -> #DIV/0! | BJ28: =BI28 -> #DIV/0!
C29: 고객경험단계별 VOC 불만사항 요약과 VOC 예시입니다. (※ 3건 미만인 경우 VOC 원문만 표출) | BG29: 9월 | BH29: =COUNTIFS('CCI raw'!$R:$R, "칭찬", 'CCI raw'!$A:$A, "202609*") / COUNTIF('CCI raw'!$A:$A, "202609*") * 100 -> #DIV/0! | BI29: =COUNTIFS('CCI raw'!$R:$R, "불만", 'CCI raw'!$A:$A, "202609*") / COUNTIF('CCI raw'!$A:$A, "202609*") * 100 -> #DIV/0! | BJ29: =BI29 -> #DIV/0!
C30: 고객경험단계 | J30: 불만사항 요약 | BG30: 10월 | BH30: =COUNTIFS('CCI raw'!$R:$R, "칭찬", 'CCI raw'!$A:$A, "202610*") / COUNTIF('CCI raw'!$A:$A, "202610*") * 100 -> #DIV/0! | BI30: =COUNTIFS('CCI raw'!$R:$R, "불만", 'CCI raw'!$A:$A, "202610*") / COUNTIF('CCI raw'!$A:$A, "202610*") * 100 -> #DIV/0! | BJ30: =BI30 -> #DIV/0!
N31: 불만 VOC 예시 | BG31: 11월 | BH31: =COUNTIFS('CCI raw'!$R:$R, "칭찬", 'CCI raw'!$A:$A, "202611*") / COUNTIF('CCI raw'!$A:$A, "202611*") * 100 -> #DIV/0! | BI31: =COUNTIFS('CCI raw'!$R:$R, "불만", 'CCI raw'!$A:$A, "202611*") / COUNTIF('CCI raw'!$A:$A, "202611*") * 100 -> #DIV/0! | BJ31: =BI31 -> #DIV/0!
C32: {{S2_complaint1_1}} | J32: {{S2_complaint1_2}} | BG32: 12월 | BH32: =COUNTIFS('CCI raw'!$R:$R, "칭찬", 'CCI raw'!$A:$A, "202612*") / COUNTIF('CCI raw'!$A:$A, "202612*") * 100 -> #DIV/0! | BI32: =COUNTIFS('CCI raw'!$R:$R, "불만", 'CCI raw'!$A:$A, "202612*") / COUNTIF('CCI raw'!$A:$A, "202612*") * 100 -> #DIV/0! | BJ32: =BI32 -> #DIV/0!
N33: 예시) {{S2_complaint1_3}}
N34: 예시) {{S2_complaint1_4}}
N35: 예시) {{S2_complaint1_5}}
C36: {{S2_complaint2_1}} | J36: {{S2_complaint2_2}}
N37: 예시) {{S2_complaint2_3}}
N38: 예시) {{S2_complaint2_4}}
N39: 예시) {{S2_complaint2_5}}
C40: {{S2_complaint3_1}} | J40: {{S2_complaint3_2}}
N41: 예시) {{S2_complaint3_3}}
N42: 예시) {{S2_complaint3_4}}
N43: 예시) {{S2_complaint3_5}}

Sheet CCI raw
